Workbook

Sheet Scoring Matrix
A1: Control_ID | B1: Clause Description | C1: Governance & Risk Requirements | D1: Key Questions to Be Asked | E1: Information / Documents to Be Checked | F1: Score_Current (0-4) | G1: Score_Prior (0-4) | H1: Restricted_or_Prohibited_Detected
A2: E1 - Evaluate | B2: Evaluation of AI use and associated risks | C2: The governing body shall evaluate proposed and existing AI use cases based on organizational objectives, values, regulatory obligations, and AI-specific risks, including potential harm, bias, misuse, and unintended consequences. | D2: • Obtain the organization’s AI use-case inventory and confirm completeness across business units.• Select a representative sample of AI use cases (including high-risk and low-risk).• Verify that each sampled use case has undergone a documented evaluation prior to approval or deployment.• Confirm the evaluation considers decision criticality, degree of automation, affected stakeholders, and potential negative outcomes.• Verify alignment of the AI use case with organizational objectives, stated values, and risk appetite.• Confirm identification and assessment of legal, ethical, and societal risks, including potential harm or bias.• Verify evidence of governing body or delegated committee review for high-risk AI use cases. | E2: • AI use-case register or inventory (current and approved versions)• AI risk and impact assessment reports aligned to ISO/IEC 23894• Business cases, proposals, or justification documents for AI initiatives• Risk appetite and tolerance statements referencing AI use• Legal, regulatory, and ethical applicability analysis (e.g., privacy, discrimination, sector rules)• Board or executive committee minutes, approvals, or decision records• Records of rejected, deferred, or modified AI proposals | F2: 4 | G2: 0 | H2: Yes
A3: E2 - Evaluate | B3: Continuous improvement and assurance | C3: The governing body shall evaluate risks arising from data use, data quality, data provenance, and dependencies within the AI ecosystem, including third-party providers and external data sources. | D3: • Obtain the list of datasets used for AI training, testing, validation, and operation.• Verify that data sources are formally identified, documented, and approved before use.• Assess whether data quality dimensions (accuracy, completeness, relevance, timeliness) are evaluated and documented.• Verify that data provenance and lineage are traceable from source to model use.• Confirm assessment of bias, representativeness, and potential discriminatory outcomes in datasets.• Identify third-party components (data providers, model vendors, cloud platforms) within the AI ecosystem.• Verify that third-party and supplier risks are evaluated prior to integration.• Confirm that data use complies with applicable legal, contractual, and ethical requirements.• Verify that governing body or delegated oversight function reviews high-risk data and ecosystem dependencies. | E3: • Data governance framework and policies• Data inventory covering AI datasets (training, testing, inference)• Data source documentation and lineage diagrams• Data quality assessment reports• Bias, fairness, and representativeness analysis reports• Privacy impact assessments (DPIA/PIA)• Third-party and supplier risk assessments• Vendor contracts and data-sharing agreements• Governing body or committee review records related to data or ecosystem risks | F3: 3 | G3: 0
A4: D1 – Direct | B4: Direction on acceptable AI use | C4: The governing body shall set clear direction on acceptable and unacceptable AI uses, based on organizational strategy, values, and a defined AI risk appetite. | D4: • Obtain the organization’s AI governance policy, principles, or equivalent governing documents.• Verify that acceptable, restricted, and prohibited AI uses are explicitly defined and documented.• Confirm that AI direction is aligned with organizational strategy, purpose, and stated values.• Verify that an AI-specific risk appetite or tolerance statement is defined and approved by the governing body.• Assess whether high-risk AI use cases are subject to enhanced approval, escalation, or additional safeguards.• Confirm that approval criteria for AI initiatives are clearly defined and consistently applied.• Verify that direction from the governing body is formally communicated to management and embedded into decision-making processes. | E4: • Board-approved AI policy, principles, or ethics charter• AI strategy, roadmap, or strategic planning documents• Risk appetite and tolerance statements specific to AI use• AI use classification (approved / restricted / prohibited)• Approval and escalation criteria for AI initiatives• Board or executive committee minutes approving AI direction• Evidence of communication of AI direction to management (memos, intranet, guidance documents) | F4: 1 | G4: 0 | H4: No
A5: D2 – Direct | B5: Accountability and decision authority | C5: The governing body shall ensure that accountability for AI-enabled decisions remains with identified human roles, and that decision authority, escalation, and override mechanisms are clearly defined and enforceable. | D5: • Obtain documentation defining accountability for AI-enabled decisions and outcomes.• Verify that accountable human roles are explicitly identified for each AI system or use case.• Confirm that accountability spans the AI lifecycle (design, deployment, operation, and retirement).• Assess whether decisions that must remain under human authority are clearly defined and documented.• Verify that escalation paths exist for AI-related issues, errors, or unexpected outcomes.• Confirm that override mechanisms (human-in-the-loop, human-on-the-loop, or kill switch) are formally defined and accessible.• Test whether AI decisions can be challenged, reversed, or suspended in practice, not only in policy.• Verify governing body or delegated oversight approval of accountability and decision authority arrangements. | E5: • RACI charts or AI accountability matrices• Role descriptions for AI owners, sponsors, and operators• AI lifecycle ownership documentation• Decision authority frameworks and delegation matrices• Escalation and incident response procedures for AI outcomes• Human-in-the-loop / human override documentation• Evidence of override testing or incident examples• Board or committee approvals related to AI accountability | F5: 4 | G5: 0
A6: D3 – Direct | B6: Direction on AI risk treatment and controls | C6: The governing body shall direct management to implement proportionate controls and risk treatments for AI risks, based on assessed risk severity, likelihood, and potential impact. | D6: • Obtain the AI risk register and risk treatment plans for in-scope AI systems.• Verify that AI risks have been evaluated using a defined risk methodology aligned with ISO/IEC 23894.• Confirm that risk treatment options (avoid, reduce, transfer, accept) are selected based on risk severity and impact.• Assess whether controls implemented are proportionate to the level of AI risk and decision criticality.• Verify that high-risk AI use cases have enhanced or layered controls as directed by the governing body.• Confirm that residual risks are formally reviewed and accepted by appropriate authority, not defaulted to management alone.• Verify that escalation criteria exist for risks exceeding defined AI risk appetite.• Confirm that management action plans are defined, tracked, and reported back to the governing body. | E6: • AI risk register and risk treatment plans (ISO/IEC 23894 aligned)• Documented AI risk assessment methodology• Control design and implementation documentation• Mapping of controls to specific AI risks• Residual risk acceptance records with approval authority• Management action plans with owners and timelines• Governing body or committee minutes directing risk treatment decisions | F6: 4
A7: M1 – Monitor | B7: Monitoring of AI performance and risk | C7: The governing body shall monitor AI systems to ensure they continue to perform as intended and that AI-related risks remain within defined and acceptable limits. | D7: • Obtain AI performance and risk monitoring reports provided to the governing body or delegated oversight function.• Verify that performance metrics are defined for AI systems and measured on a recurring basis.• Confirm that key risks related to AI (accuracy, bias, drift, misuse, degradation) are actively monitored.• Assess whether KPIs and KRIs are aligned with the organization’s AI risk appetite and decision criticality.• Verify that mechanisms exist to detect model drift, bias, or performance degradation over time.• Confirm that early warning indicators and thresholds are defined to trigger investigation or escalation.• Review periodic AI risk reviews to ensure risks remain within acceptable limits.• Verify that monitoring outcomes are reported upward and can trigger corrective action, override, or reassessment. | E7: • AI performance and monitoring reports• Defined KPIs and KRIs for AI systems• Bias, fairness, and drift monitoring outputs• Model performance trend analyses• Periodic AI risk review records• Thresholds and alert definitions for AI risk indicators• Governing body or oversight committee reports and minutes• Records of actions taken based on monitoring results | F7: 4
A8: M2 – Monitor | B8: Monitoring of incidents and compliance | C8: The governing body shall ensure that AI-related incidents, nonconformities, and compliance issues are identified, reported, escalated, and addressed in a timely and effective manner. | D8: • Obtain the AI incident and issue management process and verify it covers AI-specific incidents and near misses.• Review AI incident logs to confirm incidents are recorded, categorized, and investigated.• Verify that incident severity criteria and escalation thresholds are defined and applied consistently.• Confirm that significant AI incidents are escalated to the governing body or designated oversight committee.• Verify that regulatory, legal, and policy compliance obligations related to AI are monitored on an ongoing basis.• Review how compliance breaches or nonconformities are identified and addressed.• Confirm that corrective and preventive actions are defined, tracked, and closed.• Assess whether incident trends and compliance issues are periodically reviewed to inform governance decisions. | E8: • AI incident and issue logs (including near misses)• Incident classification and escalation procedures• Investigation and root cause analysis records• Compliance reports and internal or external audit results• Regulatory correspondence and notifications• Records of nonconformities and breaches related to AI• Corrective and preventive action (CAPA) records• Governing body or oversight committee reports and minutes | F8: 3
A9: M3 – Monitor | B9: Continuous improvement and assurance | C9: The governing body shall monitor the effectiveness of AI governance and AI risk management arrangements and require continual improvement, including independent assurance where appropriate. | D9: • Obtain records of periodic reviews of AI governance and risk management arrangements.• Verify that reviews assess effectiveness, not just existence, of governance mechanisms.• Confirm that lessons learned from AI incidents, near misses, audits, and risk reviews are formally captured.• Verify that lessons learned are translated into updates to governance direction, policies, or controls.• Assess whether independent assurance (internal audit, external audit, or expert review) is obtained for high-risk AI use cases or where required by regulation or risk appetite.• Confirm that management review outputs related to AI governance are reported to the governing body.• Verify that governance improvements are tracked, approved, and implemented.• Confirm that the AI governance framework is reviewed and updated in response to changes in technology, regulation, or organizational context. | E9: • Governance review agendas and minutes• Management review outputs covering AI governance and risk• Internal audit reports related to AI governance• External assurance or independent review reports• Lessons learned registers or post-incident reviews• Records of framework updates and version control• Improvement action plans and status tracking• Governing body approvals for governance changes

Sheet Metrics Table
A1: Metric | B1: Value_Current | C1: Value_Prior | D1: Notes (Optional)
A2: Total_AI_Systems | B2: 10 | C2: 5
A3: New_AI_Use_Cases | B3: 4 | C3: 1
A4: High_Risk_AI | B4: 7 | C4: 2
A5: Outside_Approved_Scope | B5: 0 | C5: 0

Sheet AI Landscape & Scope (Evaluate)
A1: Metric | B1: Current Status | C1: Trend (↑ ↓ →) | D1: Board Insight
A2: Total AI systems in use | B2: =_xlfn.XLOOKUP("Total_AI_Systems", tblMetrics[Metric], tblMetrics[Value_Current], "") -> 10 | C2: =_xlfn.LET( _xlpm.cur, _xlfn.XLOOKUP("Total_AI_Systems", tblMetrics[Metric], tblMetrics[Value_Current], ""), _xlpm.pri, _xlfn.XLOOKUP("Total_AI_Systems", tblMetrics[Metric], tblMetrics[Value_Prior], ""), IF(_xlpm.pri="",0, IF(_xlpm.cur<_xlpm.pri,1, IF(_xlpm.cur=_xlpm.pri,2,3))) ) -> 3 | D2: Visibility of AI footprint
A3: New AI use cases since last review | B3: =_xlfn.XLOOKUP("New_AI_Use_Cases", tblMetrics[Metric], tblMetrics[Value_Current], "") -> 4 | C3: =_xlfn.LET( _xlpm.cur, _xlfn.XLOOKUP("New_AI_Use_Cases", tblMetrics[Metric], tblMetrics[Value_Current], ""), _xlpm.pri, _xlfn.XLOOKUP("New_AI_Use_Cases", tblMetrics[Metric], tblMetrics[Value_Prior], ""), IF(_xlpm.pri="",0, IF(_xlpm.cur<_xlpm.pri,1, IF(_xlpm.cur=_xlpm.pri,2,3))) ) -> 3 | D3: Pace of AI adoption
A4: High-risk AI use cases | B4: =_xlfn.XLOOKUP("High_Risk_AI", tblMetrics[Metric], tblMetrics[Value_Current], "") -> 7 | C4: =_xlfn.LET( _xlpm.cur, _xlfn.XLOOKUP("High_Risk_AI", tblMetrics[Metric], tblMetrics[Value_Current], ""), _xlpm.pri, _xlfn.XLOOKUP("High_Risk_AI", tblMetrics[Metric], tblMetrics[Value_Prior], ""), IF(_xlpm.pri="",0, IF(_xlpm.cur<_xlpm.pri,1, IF(_xlpm.cur=_xlpm.pri,2,3))) ) -> 3 | D4: Areas needing enhanced oversight
A5: AI systems outside approved scope (Yes/No) | B5: =_xlfn.XLOOKUP("Outside_Approved_Scope", tblMetrics[Metric], tblMetrics[Value_Current], "") -> 0 | C5: =_xlfn.LET( _xlpm.cur, _xlfn.XLOOKUP("Outside_Approved_Scope", tblMetrics[Metric], tblMetrics[Value_Current], ""), _xlpm.pri, _xlfn.XLOOKUP("Outside_Approved_Scope", tblMetrics[Metric], tblMetrics[Value_Prior], ""), IF(_xlpm.pri="",0, IF(_xlpm.cur<_xlpm.pri,1, IF(_xlpm.cur=_xlpm.pri,2,3))) ) -> 2 | D5: Immediate governance concern if Yes

Sheet Strategic Alignment & Direction
A1: Area | B1: Status (Green/Amber/Red) | C1: Trend | D1: Board Question
A2: Alignment with AI strategy | B2: =IFERROR( IF(VALUE(INDEX('Scoring Matrix'!F:F, MATCH("D1 –*", 'Scoring Matrix'!A:A, 0)))>=4,"Green", IF(VALUE(INDEX('Scoring Matrix'!F:F, MATCH("D1 –*", 'Scoring Matrix'!A:A, 0)))=3,"Amber","Red")), "") -> Red | C2: =IF(('Scoring Matrix'!F4-'Scoring Matrix'!G4)>0,1,IF(('Scoring Matrix'!F4-'Scoring Matrix'!G4)<0,3,2)) -> 1 | D2: Are we using AI where we said we would? | H2: =_xlfn.XLOOKUP("D1",'Scoring Matrix'!A:A,'Scoring Matrix'!F:F,"")
A3: Alignment with organizational values | B3: =IFERROR( IF(VALUE(INDEX('Scoring Matrix'!F:F, MATCH("D1 –*", 'Scoring Matrix'!A:A, 0)))>=4,"Green", IF(VALUE(INDEX('Scoring Matrix'!F:F, MATCH("D1 –*", 'Scoring Matrix'!A:A, 0)))=3,"Amber","Red")), "") -> Red | C3: =IF(('Scoring Matrix'!F5-'Scoring Matrix'!G5)>0,1,IF(('Scoring Matrix'!F5-'Scoring Matrix'!G5)<0,3,2)) -> 1 | D3: Does any AI use conflict with our values? | H3: =_xlfn.XLOOKUP("D2",'Scoring Matrix'!A:A,'Scoring Matrix'!F:F,"")
A4: Adherence to AI risk appetite | B4: =IFERROR( IF(VALUE(INDEX('Scoring Matrix'!F:F, MATCH("D1 –*", 'Scoring Matrix'!A:A, 0)))>=4,"Green", IF(VALUE(INDEX('Scoring Matrix'!F:F, MATCH("D1 –*", 'Scoring Matrix'!A:A, 0)))=3,"Amber","Red")), "") -> Red | C4: =IF(('Scoring Matrix'!F6-'Scoring Matrix'!G6)>0,1,IF(('Scoring Matrix'!F6-'Scoring Matrix'!G6)<0,3,2)) -> 1 | D4: Are risks exceeding what we approved? | H4: =_xlfn.XLOOKUP("D1",'Scoring Matrix'!A:A,'Scoring Matrix'!G:G,"")
A5: Prohibited or restricted AI use detected (Yes/No) | B5: =IFERROR(INDEX('Scoring Matrix'!H:H, MATCH("D1 –*", 'Scoring Matrix'!A:A, 0)),"") -> No | C5: =IF( ISBLANK('Scoring Matrix'!G5), 0, IF( AND('Scoring Matrix'!G5="Yes",'Scoring Matrix'!H5="No"), 1, IF( 'Scoring Matrix'!G5='Scoring Matrix'!H5, 2, 3 )) ) -> 2 | D5: Why was this allowed to proceed? | H5: =_xlfn.XLOOKUP("D2",'Scoring Matrix'!A:A,'Scoring Matrix'!G:G,"")
A10: Trend
A11: 1 → Improving
A13: 3 → Deteriorating
A15: "Stable" → No change (0)

Sheet AI Risk Posture Summary
A1: Risk Category | B1: Current Level (Low/Med/High) | C1: Change Since Last Review (↑ ↓ →)
A2: Harm to individuals or society | B2: =IF('Scoring Matrix'!F2>=3,"Low",IF('Scoring Matrix'!F2=2,"Med","High")) -> Low | C2: =IF(('Scoring Matrix'!F2-'Scoring Matrix'!G2)>0,1,IF(('Scoring Matrix'!F2-'Scoring Matrix'!G2)=0,2,3)) -> 1
A3: Bias and discrimination risk | B3: =IF('Scoring Matrix'!F2>=3,"Low",IF('Scoring Matrix'!F2=2,"Med","High")) -> Low | C3: =IF(('Scoring Matrix'!F2-'Scoring Matrix'!G2)>0,1,IF(('Scoring Matrix'!F2-'Scoring Matrix'!G2)=0,2,3)) -> 1
A4: Legal or regulatory exposure | B4: =IF('Scoring Matrix'!F2>=3,"Low",IF('Scoring Matrix'!F2=2,"Med","High")) -> Low | C4: =IF(('Scoring Matrix'!F2-'Scoring Matrix'!G2)>0,1,IF(('Scoring Matrix'!F2-'Scoring Matrix'!G2)=0,2,3)) -> 1
A5: Data protection and privacy risk | B5: =IF('Scoring Matrix'!F3>=3,"Low",IF('Scoring Matrix'!F3=2,"Med","High")) -> Low | C5: =IF(('Scoring Matrix'!F3-'Scoring Matrix'!G3)>0,1,IF(('Scoring Matrix'!F3-'Scoring Matrix'!G3)=0,2,3)) -> 1
A6: Third-party and ecosystem risk | B6: =IF('Scoring Matrix'!F3>=3,"Low",IF('Scoring Matrix'!F3=2,"Med","High")) -> Low | C6: =IF(('Scoring Matrix'!F3-'Scoring Matrix'!G3)>0,1,IF(('Scoring Matrix'!F3-'Scoring Matrix'!G3)=0,2,3)) -> 1
A11: From Score_Current (0–4):
A13: 4–3 = Low
A15: 2 = Medium
A17: 1–0 = High
A19: Reason: lower score means weaker governance, so higher risk.

Sheet Performance & Risk Indicators
A1: Indicator | B1: Status (Green/Amber/Red) | C1: Threshold / Target | D1: Board Action if Red
A2: AI accuracy / effectiveness | B2: =IF('Scoring Matrix'!F7>=4,"Green",IF('Scoring Matrix'!F7=3,"Amber","Red")) -> Green | D2: Require corrective plan
A3: Bias or fairness indicators | B3: =IF('Scoring Matrix'!F7>=4,"Green",IF('Scoring Matrix'!F7=3,"Amber","Red")) -> Green | D3: Escalate and reassess
A4: Model drift detected (Yes/No) | B4: =IF('Scoring Matrix'!H7="Yes","Red","Green") -> Green | C4: N/A | D4: Trigger reassessment
A5: Early warning alerts triggered | B5: =IF('Scoring Matrix'!F7>=4,"Green",IF('Scoring Matrix'!F7=3,"Amber","Red")) -> Green | D5: Investigate and intervene

Sheet Incidents & Compliance(Monitor)
A1: Item | B1: This Period | C1: Open Items | D1: Board Visibility
A2: AI-related incidents | D2: Major incidents escalated
A3: Near misses | D3: Early risk signal
A4: Regulatory issues (Yes/No) | D4: Zero tolerance
A5: Policy or control nonconformities | D5: Governance gap if recurring
A14: Column B — This Period | D14: Column C — Open Items
A16: Enter the number of items identified during the current review period. | D16: Enter the number of items that remain open at the end of the period.
A18: AI-related incidents | D18: Includes items from previous periods that are not yet closed
A19: Count incidents that occurred in this assessment period.
D20: Includes items identified this period that are still open
A21: Near misses
A22: Count near misses detected during the period. | D22: Do not include closed or formally accepted items
A24: Regulatory issues (Yes/No) | D24: For Regulatory issues (Yes/No):
A25: Enter Yes if any regulatory issue occurred in the period; otherwise No.
D26: Leave blank or enter 1 if still open
A27: Policy or control nonconformities
A28: Count nonconformities identified during the period.
A31: Column D — Board Visibility
A33: Do not edit.
A34: This column is fixed explanatory text that tells the board why the item matters.
A36: Item | B36: What Column D means
A37: AI-related incidents | B37: Major incidents must be escalated
A38: Near misses | B38: Early warning signals
A39: Regulatory issues | B39: Zero tolerance — any issue escalated
A40: Policy/control nonconformities | B40: Repetition indicates governance gaps
A42: Think of Column D as the board’s lens, not data.
A44: Key rule (important)
A46: B and C = data
A48: D = interpretation
A50: Assessors never change Column D.

Sheet Risk Treatment & Actions
A1: Action | B1: Owner | C1: Status (On Track / Delayed) | D1: Board Concern
A2: High-risk AI mitigation plan | D2: Delay increases exposure
A3: Residual AI risk accepted (Yes/No) | D3: Board decision only
A4: Control enhancements required | D4: Ensures proportional controls
A14: How this table should be filled (simple rules)
A16: Row: High-risk AI mitigation plan
A18: Owner: accountable executive or role
A20: Status:
A22: On Track → plan approved & progressing
A24: Delayed → milestones missed
A26: Board Concern: fixed text (do not change)
A28: Row: Residual AI risk accepted (Yes/No)
A30: Owner: board / risk owner
A32: Status:
A34: On Track → acceptance documented
A36: Delayed → acceptance pending
... A48: Delayed → gaps remain

Sheet Assurance & Continuous Imprmt
A1: Area | B1: Status (Yes/No) | C1: Board Question
A2: AI governance review completed | C2: Are reviews happening regularly?
A3: Internal audit performed | C3: Were findings material?
A4: Independent / external assurance obtained | C4: Needed for high-risk AI?
A5: Framework updates implemented | C5: Are lessons being applied?

Sheet Decisions Required from Board
A1: Decision Required | B1: Reason | C1: Due Date | D1: Decision Status
A2: Approve new high-risk AI use | B2: Strategic impact
A3: Accept residual AI risk | B3: Above risk appetite
A4: Direct additional controls | B4: Incident or drift
A5: Commission independent review | B5: Assurance gap

Sheet Sheet10
B3: How to use this
B5: Use Data Validation for:
B9: Green / Amber / Red
B11: Yes / No
B13: Low / Medium / High
B15: Use Conditional Formatting:
B19: Red = immediate board attention
B21: Amber = watch closely
B23: Green = within tolerance
B25: One dashboard = one board pack slide, not multiple reports

Sheet Dashboard & Assessor Guide
A1: Dashboard Population & Assessor Guidance
A3: 1. General Rules (Apply to All Dashboard Sheets)
A5: Source of Truth
A6: All dashboard data must be derived from the Scoring Matrix (controls E1–M3 and assessor comments).
A8: Data Entry
A10: Dashboard values are entered once per assessment cycle
A12: Dashboard sheets are summary views, not detailed working papers
A14: First Assessment
A16: Use Trend Score = 0 (Baseline established) for all applicable sections
A20: 2. Trend Scoring (Common for All Sections)
A22: Trend Score | B22: Meaning
A23: 0 | B23: Baseline (first assessment)
A24: 1 | B24: Improvement since last assessment
A25: 2 | B25: No material change
A26: 3 | B26: Deterioration since last assessment
A28: Trend Assignment Rule
A29: Compare current results with the previous assessment.
A30: If no prior assessment exists, assign 0.
A34: 3. Dashboard Sections – Filling Guidance
A38: A. AI Landscape & Scope (Evaluate)
A40: Purpose
A41: Visibility of AI footprint and identification of unmanaged or out-of-scope AI.
A43: Filled Using
A45: E1 and E2 assessor comments
A47: Assessor Action
A49: Count AI systems identified
A51: Identify high-risk AI
... A167: If it is not documented in the Scoring Matrix comments, it must not appear on the dashboard.

Sheet Introduction& Assessor Guidance
A1: AI Governance Assessment – Introduction & Guidance
A3: Purpose of This Workbook
A5: This workbook is used to assess AI governance effectiveness at the governing-body level, aligned to Evaluate – Direct – Monitor principles.
A6: It focuses on governance, accountability, direction, and oversight, not technical AI design.
A10: Workbook Structure (What Each Sheet Is For)
A12: Sheet Name | B12: Purpose
A13: Scoring Matrix | B13: Primary working sheet; contains controls, testing procedures, evidence, comments, and scores
A14: AI Landscape & Scope (Evaluate) | B14: Summary view of AI footprint
A15: Strategic Alignment & Direction | B15: Summary of alignment with strategy and values
A16: AI Risk Posture Summary | B16: Overall AI risk exposure
A17: Performance & Risk Indicators | B17: Monitoring of AI performance and drift
A18: Incidents & Compliance | B18: AI incidents and regulatory issues
A19: Risk Treatment & Actions | B19: Status of AI risk treatments
A20: Assurance & Continuous Improvement | B20: Governance review and assurance
A21: Decisions Required from Board | B21: Matters requiring governing-body decisions
A23: Rule: Dashboard sheets are summaries only.
A24: All evidence and judgment must be recorded in the Scoring Matrix.
A28: Assessor Responsibilities
A30: Follow the testing procedure for each control (E1–M3)
A32: Review the listed evidence
A34: Record clear comments
A36: Assign a score based on evidence
A38: Escalate material issues to the board
A40: Assessors must not rely on verbal assurances alone.
A44: Control Scoring Scale (Applies to All Controls)
A46: Score | B46: Meaning
A47: 0 | B47: Not implemented
A48: 1 | B48: Ad hoc / informal
A49: 2 | B49: Defined but weak or inconsistent
A50: 3 | B50: Implemented and operating
A51: 4 | B51: Effective and improving
A53: Scoring rule:
A54: If a control exists only on paper and is not used in practice → Score ≤ 2
A58: Control-Specific Scoring Anchors
A60: Evaluate (E1, E2)
A62: 0–1: No or informal evaluation
A64: 2: Evaluation documented but limited use
A66: 3: Evaluation informs decisions
A68: 4: Evaluation reviewed and improved
A70: Direct (D1, D2, D3)
...
