Workbook

Sheet Introduction
A3: INTRODUCTION & USER GUIDE
A5: AI Data Privacy Maturity Assessment Tool
A7: BSI Digital Trust
A9: This workbook supports the assessment of an organization’s AI data privacy posture across multiple domains.
A10: It is designed for assessors to evaluate privacy controls, assign maturity scores, and automatically generate domain-level results and visual dashboards.
A12: The tool helps identify how AI systems collect, process, store, infer, and output personal data, and whether privacy risks are being managed appropriately across the AI lifecycle.
A14: Use this guide to understand how each sheet functions and how to complete the assessment correctly.
A16: Scoring Matrix
A18: This sheet is where the full AI privacy assessment is completed.
A20: How to Use This Sheet
A22: 1. Review each control requirement row-by-row.
A24: 2. Use the Test Procedure column to guide your evaluation.
... A150: Weight values should remain set to 3 unless the model design is changed.

Sheet Scoring Matrix
A1: Domain Name | B1: Clause / Control No. | C1: Control Description | D1: Requirements (Shall) | E1: Testing Procedure | F1: Evidence to Be Reviewed | G1: Maturity (0-5) | H1: Weight (3) | I1: Weighted Score (G*H) | J1: Comments/ Assessment Notes
A2: Scope Definition | B2: 2.1 | C2: Identification of AI systems processing personal or inferable data | D2: The organization shall identify and document all AI systems that process personal data, pseudonymized data, biometric data, behavioral data, or data capable of identifying individuals through inference. | E2: • Review AI system inventory for completeness and accuracy. • Interview AI, privacy, security, and data engineering teams to confirm no systems are missing, including shadow/unauthorized AI use. • Verify inclusion of all training, fine-tuning, inference, embedded AI features, vector stores, and third-party AI services. • Validate that inferable data (embeddings, behavioral patterns, model-derived attributes) is included in scope. • Check linkage between system inventory, model registry, data flow diagrams, and architecture diagrams. | F2: • AI system inventory (with model names, versions, owners, purpose, dataset references). • Data flow diagrams showing personal/inferable data paths. • Model registry entries including training, tuning, and inference models. • Architecture diagrams showing data ingestion, feature stores, vector databases, and inference endpoints. • List of third-party AI APIs/services. • Documentation confirming inclusion of embedded AI in existing products/platforms. | G2: 5 | H2: 3 | I2: =G2*H2 -> 15
A3: Scope Definition | B3: 2.1.1 | C3: Inclusion Criteria | D3: AI systems shall be included in scope if they use, generate, transform, infer, or expose personal data, pseudonymized data, biometric data, behavioral data, or any data capable of identifying individuals through inference at any stage of the AI lifecycle (collection, training, tuning, inference, storage, or output). | E3: • Confirm inclusion criteria are applied consistently across all business units and AI workflows. • Sample AI systems (training models, inference endpoints, embedded AI features, vector stores, LLM integrations) to validate classification accuracy. • Verify that inferable data (embeddings, user behavior patterns, model-derived attributes) is included in the scoping methodology. • Interview privacy, AI/ML, and engineering teams to confirm no systems are omitted. | F3: • Inclusion criteria document defining how personal and inferable data triggers scope inclusion. • List of in-scope vs. out-of-scope AI systems with justification. • Cross-functional validation records (AI, Privacy, Security). • Mapping of datasets to AI systems showing why each is included/excluded. | G3: 0 | H3: 3 | I3: =G3*H3 -> 0
A4: Scope Definition | B4: 2.1.2 | C4: Third-party AI Systems | D4: The organization shall include third-party AI services, APIs, or hosted AI capabilities that process personal data, pseudonymized data, behavioral data, biometric data, or any data that can lead to identification by inference. | E4: • Review third-party vendor list and confirm all AI-enabled services are included. • Confirm AI API usage across teams (e.g., ChatGPT API, cloud AI services, analytics AI features). • Validate data-sharing agreements, DPAs, and permitted use clauses. • Verify that external model providers do not retain, train, or derive data beyond contractual terms. • Interview engineering, procurement, and privacy teams to identify unreported or shadow AI tools. | F4: • Vendor inventory including AI services and APIs. • Contracts/DPAs with explicit AI data-use clauses. • API usage logs showing data sent to external AI providers. • Procurement records for SaaS tools with embedded AI. • Third-party risk assessments. • Data flow diagrams showing outbound data to external AI. | G4: 5 | H4: 3 | I4: =G4*H4 -> 15
A5: Scope Definition | B5: 2.1.3 | C5: Inference-Based Identification | D5: AI systems capable of inferring, predicting, or reconstructing personal attributes (e.g., identity, demographics, behavior, health traits, preferences, biometric features) from non-identifying inputs shall be classified as in scope. This includes models that generate embeddings, probabilistic scores, or inferred labels that can reveal or approximate personal characteristics. | E5: • Test model outputs to detect potential inference of personal or sensitive attributes (demographics, behavior, location, identity signals). • Interview ML engineers to understand model architecture and whether inference capabilities are intentional, emergent, or incidental. • Review feature engineering steps and embedding models to determine whether they enable identity reconstruction. • Confirm that systems capable of predicting or inferring user traits—even without explicit personal data—are included in scope. | F5: • Model testing results showing inferred attributes or privacy leakage. • Privacy impact assessments identifying inference-related risks. • Output evaluation logs documenting inference behavior. • Feature engineering documentation. • Embedding generation and vector store documentation. | G5: 1 | H5: 3 | I5: =G5*H5 -> 3
A6: Data Processing | B6: 2.2 | C6: AI-Related Data Processing Activities Across the Lifecycle | D6: The organization shall document all AI-related data processing activities across the full lifecycle, including data collection, ingestion, labeling, annotation, transformation, feature engineering, embedding creation, training, fine-tuning, inference, retention, storage, sharing with third parties, and deletion. Documentation shall specify what personal, sensitive, or inferable data exists at each stage.Data collection must be lawful, purpose-limited, minimized, and transparent. Dataset preparation must be documented, showing suppression of identifiers, de-identification, annotation controls, and privacy-risk mitigation. Training and fine-tuning using personal data must be documented and risk-assessed. Inference must be monitored for leakage or sensitive-attribute inference. Retention/deletion must follow defined schedules and automated deletion workflows. Automated decision-making (ADM) must be documented with safeguards and user rights. Third parties processing AI-related data must meet privacy and security obligations. | E6: • Review AI-specific ROPA or equivalent documentation to confirm full mapping of data processing activities from collection → ingestion → preparation → training → inference → storage → deletion. Validate completeness of data categories (personal, sensitive, behavioral, biometric, inferable).• Inspect all data collection pipelines; confirm lawful basis, consent records, contractual/legal justification, transparency notices, and minimization practices. Interview data engineers to confirm no undocumented ingestion pipelines exist.• Review dataset preparation workflows, including cleaning, normalization, labeling, annotation, feature engineering, pseudonymization, and de-identification. Validate suppression of identifiers, transformed attributes, and access controls for annotators.• Evaluate training and fine-tuning datasets, lineage, preprocessing steps, DPIA/PIA documentation, and confirm no shadow/undocumented datasets are used.• Test inference outputs for direct/indirect privacy leakage, reconstruction risks, attribute inference, and evaluate guardrail filters, redaction layers, and monitoring dashboards.• Review retention schedules for all AI datasets, embeddings, inference logs, checkpoints, vector stores; confirm deletion logs, TTL rules, and lifecycle automation remove expired or intermediate data.• Assess ADM workflows including profiling logic, scoring, eligibility decisions, human-in-the-loop controls, override mechanisms, and user notification processes.• Review third-party DPAs and contracts; verify AI-related restrictions on training, retention, inference, reuse, and subprocessor transparency. Validate vendor assessments, certifications, and periodic reviews. | F6: • AI Records of Processing Activities (ROPA) covering full AI data lifecycle.• Data source inventory; lawful basis documentation; consent records; privacy notices with AI disclosures; ingestion pipeline documentation (APIs, ETL, automated loaders).• Transformation scripts; annotation guidelines; feature engineering documentation; pseudonymization/de-identification logs; access control logs for annotators; masking/suppression records.• Training dataset documentation; DPIA/PIA reports; training logs; dataset lineage; approvals of training datasets; schema documentation.• Output leakage test logs; guardrail configuration files; inference monitoring dashboards; filtering rules; evaluation cycle evidence.• Retention policy; storage lifecycle configurations (S3 TTL, Blob lifecycle, GCS lifecycle); automated deletion logs; deletion tickets; retention/deletion mapping per AI system.• ADM decision logs; profiling documentation; transparency notices; user notification evidence; human oversight logs; ADM risk assessments.• Vendor DPAs; SOC 2/ISO 27001/ISO 27701 certificates; vendor AI risk assessments; subprocessor lists; contractual AI-use restrictions; third-party data flow diagrams; vendor reassessment records. | G6: 3 | H6: 3 | I6: =G6*H6 -> 9
A7: Boundaries | B7: 2.3 | C7: Organizational Boundaries for AI Privacy | D7: The organization shall define all internal functions and external entities involved in AI data processing. Internal teams that collect, transform, label, train, evaluate, or consume AI data must be documented. External processors, vendors, cloud services, and subprocessors must be included in scope. Global data transfers for AI must be documented. Supporting infrastructure—including feature stores, pipelines, training systems, inference environments, labeling systems, and registries—must be included in the AI privacy boundary. Boundaries must distinguish controllers, processors, subprocessors, and responsibilities for privacy compliance across the full AI lifecycle. | E7: • Review boundary documentation to confirm which business units, internal teams (AI/ML, Data Engineering, Governance, Privacy, Security, Legal, Compliance, Operations), external vendors, and cloud providers participate in AI data processing activities such as collection, transformation, labeling, training, model evaluation, inference, storage, or hosting.• Interview stakeholders to validate that internal contributors (e.g., analytics teams, DevOps hosting models, product teams using inference outputs) and external entities (annotation vendors, SaaS AI providers, cloud ML pipelines) are accurately identified and mapped.• Confirm controller/processor/subprocessor designations and verify that DPAs align with AI data processing roles.• Validate that all international transfers—dataset movement, offshore labeling, global training clusters, cross-region inference—are documented and covered by SCCs/BCRs/TIAs.• Inspect architecture diagrams to ensure all AI-related infrastructure components (feature stores, data pipelines, vector databases, registries, training clusters, inference endpoints) are included in boundary mappings and reflect actual deployed environments.• Evaluate whether data flows include privacy controls (access restrictions, logging, lineage tracking, retention enforcement).• Verify boundaries include cloud AI services and pipelines that process personal data (AWS Sagemaker, Vertex AI, Azure ML). | F7: • AI governance boundary maps showing internal teams, data flows, and external entities.• RACI matrices and team ownership lists identifying responsibilities for dataset approvals, transformations, training, evaluation, and monitoring.• Vendor lists annotated with AI processing roles, DPAs, AI-specific contractual restrictions, subprocessor disclosures, vendor risk assessments, and audit reports.• Data transfer documentation including SCCs/BCRs, TIAs/TRAs, cross-region transfer logs, and geo-boundary diagrams for AI systems.• Architecture diagrams covering all AI pipelines, feature stores, training clusters, inference endpoints, registries, ETLs, and API gateways.• Pipeline logs showing ingestion, transformation, feature generation, training triggers, inference traffic, and synchronization events.• Configuration documentation (Terraform/CloudFormation/IaC) specifying AI-related infrastructure pathways.• IAM/access logs demonstrating role-based access to AI components, storage layers, and cloud pipelines. | G7: 0 | I7: =G7*H7 -> 0
A8: Regulatory Context | B8: 2.4 | C8: Applicability of Global AI Privacy Requirements | D8: The organization shall map applicable privacy laws and contractual obligations to AI systems. All data use must comply with legal and contractual restrictions. Global data protection requirements must be applied to AI data flows. Suppliers must meet AI privacy standards. The organization shall identify privacy laws, regulatory requirements, sectoral obligations, and cross-border transfer rules impacting AI data processing. Contractual restrictions (DPAs, MSAs, SLAs) governing AI data use—including limitations on training, fine-tuning, profiling, retention, and automated decision-making—must be reflected in AI workflows. AI systems must comply with jurisdictional requirements for international data transfers using SCCs, BCRs, adequacy decisions, or other approved mechanisms. Third-party vendors participating in the AI lifecycle must comply with AI privacy requirements, provide attestations, restrict secondary use, disclose subprocessors, and maintain certifications or equivalent assurances. | E8: • Review the global AI privacy applicability matrix to confirm mapping of all applicable privacy laws and regulatory requirements (GDPR, CPRA, LGPD, PDPA, PIPEDA, HIPAA, sectoral rules, AI-specific frameworks such as EU AI Act, OECD, NIST AI RMF).• Validate that each AI system is evaluated for handling personal, sensitive, biometric, behavioral, or inferred data, and that legal/contractual obligations are correctly mapped.• Assess the completeness of contractual restrictions in DPAs, MSAs, SLAs—including purpose limitation, data-use prohibitions, retention limits, profiling restrictions, automated decision-making constraints, and cross-border limitations.• Interview teams to confirm no undocumented repurposing or expanded AI use is occurring without customer approval.• Review cross-border transfer mechanisms for all AI data flows (training, fine-tuning, annotation, evaluation, inference, model hosting, feature stores, ML Ops systems). Confirm SCCs, BCRs, TIAs, routing controls, and regional deployment compliance.• Validate controls preventing shadow transfers via third-party AI tools, global inference endpoints, or cloud model APIs.• Assess third-party suppliers’ adherence to AI privacy standards—confirm attestations, contractual AI-specific restrictions, subprocessor disclosures, SOC 2 AI controls, NIST AI RMF alignment, ISO 42001 readiness, and annual reassessments.• Verify governance ensures updates when new jurisdictions, AI models, or data categories introduce new obligations. | F8: • Privacy law applicability matrix covering all AI data uses and system categories.• Legal assessments mapping regulatory requirements to AI system processing (training, inference, profiling, ADM).• Compliance mapping tables showing alignment between laws, controls, and responsible teams.• DPAs, MSAs, SLAs with AI-related restrictions (training prohibitions, purpose-limitation clauses, retention limits, cross-border conditions).• Approval logs for exceptions or explicit customer consent for expanded AI use.• SCCs, BCRs, adequacy evidence, and TIA/DTIA assessments supporting AI dataset transfers.• Cross-border data transfer logs, ML platform routing diagrams, cloud region configuration documentation.• Vendor attestations confirming AI data-handling restrictions and lawful use.• Subprocessor lists, vendor compliance reports, external audit summaries (SOC 2 with AI controls, ISO certifications).• Supplier model/data-handling protocols, evidence of compliance monitoring, and periodic reassessments. | H8: 3 | I8: =G8*H8 -> 0
A9: Lifecycle | B9: 2.5 | C9: Application of Privacy Controls Across the AI Lifecycle | D9: AI privacy controls must be consistently implemented at every phase of the AI lifecycle. This includes ensuring lawful and transparent data collection; enforcing privacy-preserving transformations during data preparation; performing privacy risk assessments prior to model training; embedding technical and organizational safeguards in deployment workflows; monitoring inference outputs for privacy leakage or unauthorized attribute prediction; implementing continuous oversight mechanisms to detect drift or misuse; and applying strict retention, archival, and deletion procedures when models or datasets are retired. Controls must be aligned with regulatory obligations and internal governance frameworks and must be traceable across all lifecycle stages to demonstrate end-to-end accountability for AI privacy. Each AI lifecycle stage must have clearly documented privacy controls that define how personal and inferable data is handled from initial collection to final decommissioning. Controls must specify privacy risks, required safeguards, approval steps, validation checkpoints, data handling instructions, and responsibilities for all teams involved. These controls must be mapped to regulatory obligations and integrated into operational SOPs so that privacy requirements are consistently applied across data collection, preparation, model training, validation, deployment, monitoring, drift detection, incident handling, and retirement. Documentation must demonstrate a structured, end-to-end privacy governance model that ensures no lifecycle stage introduces unmitigated privacy risk. | E9: • Review lifecycle documentation to verify privacy steps are explicitly integrated into every lifecycle phase (collection, preprocessing, development, training, validation, deployment, runtime monitoring, drift detection, incident response, and retirement).• Inspect operational controls such as privacy risk assessment gates, approval workflows, privacy checkpoints, drift monitoring dashboards, and model-decommissioning procedures.• Validate that decommissioning steps include removal of training datasets, logs containing personal or inferable data, cached artifacts, and model versions capable of inferring personal attributes.• Evaluate workflows from each lifecycle stage to confirm mandatory privacy protections (minimization, legal basis validation, DPIA gates, leakage testing, monitoring alerts, retention & deletion checks) are embedded.• Confirm approval workflows include AI privacy review and documented sign-off checkpoints.• Interview ML, data, and engineering teams to verify lifecycle controls are consistently followed and that roles for AI privacy oversight are clear.• Validate traceability mechanisms (audit logs, workflow history, tooling) that demonstrate lifecycle controls were executed as required without gaps. | F9: • AI lifecycle model and end-to-end lifecycle documentation.• SOPs for AI lifecycle stages (collection → retirement).• Privacy checkpoints in development and deployment workflows.• Model decommissioning procedures and deletion logs.• Privacy risk assessment templates, DPIA gates, and approval workflow records.• Monitoring dashboards showing privacy alerts, drift detection, or leakage flags.• Lifecycle control matrices and stage-specific privacy checklists.• Workflow history logs or audit trails showing that lifecycle privacy controls were executed and approved. | H9: 3 | I9: =G9*H9 -> 0
A10: Scope Exclusions | B10: 2.6 | C10: Criteria & Justification for Excluding AI Systems | D10: AI systems shall be excluded from the AI privacy scope only when it is demonstrably proven that the system does not process, transform, store, infer, or generate any personal data or any data that could reasonably lead to identification through inference. Documentation must clearly justify the exclusion and demonstrate that no lifecycle stage—collection, preparation, training, inference, monitoring, or outputs—includes personal or inferable data. Exclusions must undergo a formal review and approval process by privacy, legal, data governance, and AI governance functions to prevent incorrect exclusion of systems capable of indirect identification, attribute inference, or unintended privacy risk. Exclusions shall be fully documented and approved by AI privacy governance. The justification must clearly demonstrate why the system qualifies for exclusion and include analysis of inputs, intermediate transformations, trained model behavior, outputs, and monitoring logs to ensure no inference risk exists. All exclusion rationales must follow an approval workflow and periodic revalidation process. | E10: • Review the exclusion inventory to confirm completeness and accuracy of systems considered out-of-scope.• Sample excluded systems to evaluate whether any lifecycle stage could process or generate personal or inferable data.• Validate that exclusion justifications include technical evidence such as schema reviews, output analysis, data flow tracing, architectural diagrams, and confirmation of non-inferable outputs.• Confirm closure of a formal review and approval workflow involving privacy, legal, data governance, and AI governance functions.• Verify that systems were not self-approved by system owners and required independent sign-off.• Assess periodic revalidation records to ensure exclusions remain accurate as systems evolve or ingest new data types.• Confirm monitoring or governance logs exist to demonstrate systems have not changed or begun processing personal data. | F10: • Exclusion justification forms and approval records.• Governance approval logs (privacy, legal, AI governance).• System architecture diagrams or schema documentation proving absence of personal or inferable data.• Data flow diagrams confirming non-personal data pathways.• Output analysis and model behavior evidence demonstrating no inference risk.• Review logs showing periodic revalidation of exclusions.• Technical evidence supporting exclusion (e.g., monitoring logs, transformation analysis, intermediate artifacts). | H10: 3 | I10: =G10*H10 -> 0
A11: KPI Domain: Re-ID & Leakage | B11: 3.1 | C11: Re-Identification Risk Score, Privacy Leakage Events, and Model Memorization Indicator | D11: The organization shall measure and monitor re-identification (re-ID) risk at defined intervals using documented quantitative or qualitative methods, maintaining a scoring model that evaluates the likelihood that personal, pseudonymized, or transformed data used in AI systems could be linked back to an individual. The score shall incorporate dataset composition, model outputs, transformation techniques, and inference behavior, with trends monitored, thresholds defined, and remediation triggered when risk increases. The organization shall also track, record, and analyze all privacy leakage events arising from AI model outputs, including memorized personal data, unintended sensitive attribute exposure, verbatim reproduction of training data, or inference-based disclosures. Leakage detection must be proactive through red-team tests, adversarial queries, and automated monitoring tools, with all events logged, categorized, tied to remediation, and fed into model updates. The organization shall further monitor for model memorization using probing tests, extraction attempts, nearest-neighbor checks, and other evaluation tools. Thresholds must be defined for acceptable memorization risk, and any confirmed instance of memorized personal data must trigger mitigation, retraining, dataset correction, or control adjustments. | E11: • Review the re-ID scoring methodology for completeness, appropriate inputs, and alignment with privacy risk principles. Validate that scoring evaluates training data, synthetic data (if used), transformation processes, and model outputs. Inspect a sample of re-ID tests to ensure correct execution and evaluate whether elevated scores triggered mitigation actions.• Inspect privacy leakage event logs to confirm completeness, categorization, severity tagging, and linkage to remediation. Validate that leakage detection mechanisms (automated scans, red-team tests, adversarial queries, prompt probes) exist, are regularly executed, and cover all relevant model types. Run sample output tests to validate controls preventing re-exposure of previously leaked data. Confirm remediation actions were triggered, documented, and closed.• Review model memorization testing methodology and frequency. Validate that probing tests, extraction attempts, nearest-neighbor similarity checks, and adversarial evaluations were conducted. Inspect whether detected memorization events resulted in mitigation or retraining. Execute sample memorization probes to confirm that controls prevent resurfacing of personal data from training datasets. | F11: • Re-ID assessment logs and scoring trend dashboards• Scoring methodology documentation• Evidence of triggered remediation steps for elevated risk scores• Privacy leakage event logs and categorization records• Red-team testing reports• Automated leakage scan outputs• Root-cause analysis and remediation documentation• Memorization test logs• Probing/extraction test reports• Similarity analysis results and nearest-neighbor mappings• Remediation, retraining, and dataset-correction records | H11: 3 | I11: =G11*H11 -> 0
A12: KPI Domain: Data Governance | B12: 3.2 | C12: Dataset Minimization, Lawful Basis Validation, Retention & Deletion Compliance | D12: 3.2.a: Measure personal data minimization level. 3.2.b: Measure % of datasets with lawful basis. 3.2.c: Measure retention/deletion adherence. | E12: • Review preprocessing workflows to assess how personal data is minimized, including redaction, anonymization, feature reduction, or pseudonymization steps. • Inspect dataset attribute lists and data dictionaries to verify removal of unnecessary or high-risk personal data elements before AI model training or inference. • Interview dataset owners to understand minimization criteria and confirm consistency across datasets. • Inspect dataset source records to verify that a lawful basis exists for each dataset (e.g., consent, contract, legal obligation, legitimate interest). • Cross-check dataset provenance documentation and confirm no dataset is used beyond its authorized purpose or processing justification. • Validate how the “% of datasets with lawful basis” metric is calculated and maintained. • Review deletion logs and system audit trails to ensure datasets are deleted or archived according to defined retention schedules. • Compare system behavior against the retention policy to confirm no dataset exceeds its permitted lifecycle. • Check approval records for retention timelines and evaluate any exceptions or overrides. • Verify that retention and deletion activities are recorded, traceable, and mapped to AI lifecycle stages. | F12: • Dataset minimization documentation (attribute removal logs, preprocessing workflows, redaction/pseudonymization evidence). • Data dictionaries and preprocessing scripts. • Lawful basis records (registers, consents, contractual clauses, DPAs, provenance statements). • Dataset source documentation and purpose-limitation statements. • Retention audit logs and deletion logs showing adherence to schedules. • Retention policies and approved retention schedules. • System-generated deletion reports, audit trails, and exception/override approvals. | H12: 3 | I12: =G12*H12 -> 0
A13: KPI Domain: Lifecycle Controls | B13: 3.3 | C13: PIA/DPIA Completion Rate, Model Change Privacy Review Rate, Drift Monitoring Frequency | D13: The organization shall track and maintain oversight of lifecycle-related privacy KPIs, including completion of PIA/DPIA assessments for all AI systems, ensuring assessments are conducted before collection, preparation, training, deployment, or significant updates. The organization shall also track privacy review rates for model changes, requiring that all material updates—including retraining, feature changes, dataset modifications, and algorithmic adjustments—undergo documented privacy impact review and approval before implementation. Additionally, the organization shall regularly monitor AI systems for privacy drift, defined as changes in model behavior, outputs, or data distributions that may introduce new privacy risks such as re-identification, leakage, or unintended inference. Drift monitoring schedules, thresholds, alerts, and remediation steps must be documented, consistently executed, and reviewed for completeness. | E13: • Review the PIA/DPIA inventory to validate that all in-scope AI systems have completed and current assessments. Check whether assessments were performed before deployment or major system updates. Inspect a representative sample of assessments to confirm inclusion of privacy risk analysis, mitigation steps, and sign-off by required governance functions.• Review model change logs to confirm privacy review coverage for all model updates. Inspect approval workflows to ensure required stakeholders (privacy, legal, governance, ML engineering) reviewed and approved changes prior to deployment. Verify that changes impacting data inputs, outputs, or model logic triggered mandatory privacy reviews.• Inspect drift monitoring frameworks, dashboards, and logs to confirm monitoring frequency aligns with risk levels. Validate that drift detection covers privacy-impacting changes such as attribute inference behavior, leakage signals, or emerging re-identification risk. Confirm alerts triggered remediation and that follow-up actions were documented and closed. | F13: • PIA/DPIA inventory list and completed assessment packages• Approval records and workflow logs for model change reviews• Model update logs with privacy review annotations• Drift monitoring logs, dashboards, and reports• Records of triggered drift alerts and remediation steps | H13: 3 | I13: =G13*H13 -> 0
A14: KPI Domain: Transparency | B14: 3.4 | C14: DSAR Fulfillment Time, Explainability Requests, Consent Accuracy | D14: The organization shall track and maintain transparency-related KPIs across AI systems, including DSAR fulfillment time, completion of explainability requests, and accuracy of consent mapping. The organization shall ensure DSARs (access, deletion, correction, objection, opt-out) involving AI data or AI-generated outputs are processed within legally mandated timelines and in accordance with privacy workflow requirements. Explainability request processes must allow individuals, regulators, or internal stakeholders to obtain clear, meaningful explanations of AI model logic, inputs, and outputs where applicable; these requests must be logged, tracked, and completed within defined timelines. The organization shall also maintain accurate consent mapping for all datasets used in AI systems, ensuring that data processing activities align with the individual’s consent status, legal basis, withdrawal actions, and purpose limitations. Any mismatch between consent status and AI data usage must trigger remediation. | E14: • Review DSAR workflow documentation, SLAs, and process ownership to validate that AI-related DSARs follow required timelines and escalation procedures. Inspect a representative sample of DSAR cases involving AI inputs or outputs to confirm correct routing, validation, and response steps. Verify that dependency systems (model outputs, derived data, logs) are included in DSAR data retrieval procedures.• Examine explainability request logs to confirm proper intake, triage, assignment, and completion. Validate that explainability documentation provides meaningful insight into data sources, model behavior, decision logic, and risk mitigations. Check whether delays or escalations were recorded and resolved. Confirm that explainability mechanisms align with applicable regulatory requirements (e.g., GDPR Art. 22, AI-related transparency duties).• Validate consent-mapping accuracy by reviewing how consent is captured, stored, propagated to AI pipelines, and enforced during data processing. Inspect linkage mechanisms between raw data, training datasets, feature stores, and model outputs to confirm consent states are consistently applied. Run sample checks on datasets used in training or inference to verify they reflect correct consent status and that withdrawn or restricted data is excluded. | F14: • DSAR logs, fulfillment metrics, workflow SLAs, and case files• Explainability request logs, generated explanations, and approval records• Consent logs, consent-mapping documentation, linkage validation reports, and data lineage evidence showing correct enforcement of consent in AI pipelines | I14: =G14*H14 -> 0
A15: KPI Domain: Third-Party | B15: 3.5 | C15: Vendor Privacy Compliance & Unauthorized Training Events | D15: Track vendor privacy KPI. Log unauthorized vendor training. | E15: • Review vendor privacy assessments, vendor KPIs, and risk tiering results to confirm whether vendors meet required AI privacy, data protection, and contractual obligations. Validate that vendor compliance metrics include adherence to DPAs, training restrictions, data-handling rules, and AI-specific contractual controls. • Inspect third-party monitoring reports and confirm whether issues such as non-compliance, delayed remediation, or violations of privacy commitments were raised and addressed. • Check incident reports for unauthorized vendor training events, including improper use of customer data for model training, fine-tuning, or evaluation. Verify that all such events were logged, investigated, and remediated. • Evaluate escalation workflows to confirm that vendor misuse (e.g., shadow training, undisclosed subprocessors, storage of training data in unapproved locations) is detected and reported. • Review whether ongoing vendor oversight mechanisms (quarterly reviews, scorecards, audits) accurately track compliance trends and trigger corrective actions when performance drops below threshold. | F15: • Vendor scorecards showing privacy KPI performance • Vendor risk assessments and periodic review reports • Third-party audit summaries and compliance dashboards • Training breach logs documenting any unauthorized vendor model-training incidents • Incident investigation reports, root-cause analysis, and remediation evidence • DPA compliance status and contractual obligation tracking records | H15: 3 | I15: =G15*H15 -> 0
A16: KPI Domain: Incident Response | B16: 3.6 | C16: Incident Response Time & Emerging Privacy Risk Alerts | D16: Measure response time for privacy incidents. Track new AI privacy risks. | E16: • Review incident response workflows to ensure privacy incidents—including leakage, re-identification events, unauthorized model behavior, or vendor misuse—are captured, triaged, escalated, and resolved within defined response timelines. • Validate that the organization measures actual response times against internal SLAs and AI-specific thresholds (e.g., detection-to-containment time, containment-to-notification time). • Inspect incident records to determine whether root-cause analysis, remediation, and follow-up actions were completed. • Review monitoring systems, dashboards, and automated alerting tools used to identify emerging AI privacy risks (e.g., model drift generating sensitive attributes, new inference risks, anomalous model outputs). • Verify that new risk alerts are logged, categorized, reviewed by privacy/AI governance teams, and that risk owners are assigned for investigation. • Evaluate whether alerts triggered updates to controls, model retraining, additional monitoring, or risk acceptance decisions. | F16: • Incident logs & response timeline reports • Workflow records showing triage and escalation actions • Root-cause and remediation documentation • Monitoring system alert logs for AI privacy risks • Risk register updates tied to new alerts • AI model drift dashboards showing privacy-related triggers • Governance review notes confirming risk evaluation and closure | H16: 3 | I16: =G16*H16 -> 0
A17: KPI Domain: Reporting | B17: 3.7 | C17: KPI Reporting Requirement | D17: Report AI privacy KPIs to management. | E17: • Review the end-to-end reporting process for AI privacy KPIs, including how KPI data is aggregated, validated, and formatted for management reporting. • Confirm that reporting occurs on a defined schedule (e.g., monthly, quarterly) and that timelines are consistently met. • Inspect reporting workflows to verify that responsible owners review and approve KPI results before presentation. • Assess whether KPI dashboards or reports include all required domains—Re-ID, Leakage, Data Governance, Lifecycle Controls, Transparency, Third-Party, Incident Response. • Validate that reports highlight trends, anomalies, threshold breaches, and required remediation actions. • Confirm that reports are circulated to senior stakeholders (e.g., privacy governance board, AI oversight committee, legal leadership) and that follow-up actions are documented. • Check that historical reports are retained and version-controlled to demonstrate continuity and traceability of KPI monitoring. | F17: • KPI summary reports • Reporting schedules & calendars • Approval emails or workflow records showing management sign-off • KPI dashboards showing trend analysis • Governance meeting minutes where KPIs were reviewed • Evidence of follow-up actions from prior KPI reviews | H17: 3 | I17: =G17*H17 -> 0
A18: Core Risk Theme | B18: 4.1 | C18: Data Collection Risk | D18: Identify risks in how personal data is collected for AI use. | E18: • Review all data sources feeding AI systems (training, fine-tuning, inference logs, derived datasets) to confirm legality and compliance with privacy frameworks. • Validate that the method of data collection aligns with stated purpose, transparency notices, and user expectations. • Confirm a valid lawful basis exists for each dataset (consent, contract, legitimate interests, statutory basis). • Check whether sensitive, biometric, or behavioral data triggers enhanced collection requirements. • Review whether undocumented or shadow data collection paths exist. • Assess whether minimization principles were applied during collection and whether unnecessary or high-risk attributes were excluded. • Verify that data subjects were informed where required and that collection practices do not introduce bias or unintended privacy exposure. | F18: • Collection logs and data source inventories • Lawful basis assessments and mapping • Consent or notice records • Data ingestion documentation (ETL flows, pipelines) • Risk assessments identifying collection-related gaps • Evidence of minimization reviews | H18: 3 | I18: =G18*H18 -> 0
A19: Core Risk Theme | B19: 4.2 | C19: Dataset Preparation & Transformation Risk | D19: Identify risks in labeling, transforming, or de-identifying data. | E19: • Review all dataset preparation steps—including labeling, annotation, feature engineering, normalization, augmentation, vectorization, embedding creation, masking, pseudonymization, and de-identification. • Assess whether any transformation step introduces new privacy exposure, inferable attributes, or leakage risk. • Validate that de-identification processes include documented methods (e.g., k-anonymity, noise injection, suppression, tokenization) and that risk of re-identification has been evaluated. • Confirm labeling processes prevent annotators from accessing unnecessary personal or sensitive data. • Check that transformation pipelines follow minimization principles and remove unnecessary identifiers or quasi-identifiers. • Ensure no undocumented preprocessing scripts exist and that data lineage reflects all transformation steps. | F19: • Inspect dataset preparation workflows, preprocessing scripts, and transformation pipelines for completeness and accuracy. • Validate logs showing execution of de-identification, masking, or pseudonymization steps. • Review labeling instructions and annotation access controls to ensure annotators do not see unnecessary personal data. • Examine de-identification assessments for evidence of residual re-ID risk evaluation. • Confirm that derived features or embeddings do not allow reconstruction or inference of personal data. • Verify that all preparation steps are documented and approved by data governance or privacy teams. | H19: 3 | I19: =G19*H19 -> 0
A20: Core Risk Theme | B20: 4.3 | C20: Model Training & Learning Risk | D20: Identify risks in training that cause memorization or unintended learning of personal or sensitive data. | E20: • Review all model training controls to ensure personal or inferable data is not memorized, reproduced, or unintentionally learned by the model. • Confirm that training datasets undergo privacy review, quality checks, and minimization before use. • Validate that defenses such as regularization, differential privacy, noise injection, or batching strategies are applied if required. • Ensure training workflows include checks for unintended learning, such as leakage of sensitive attributes, identity inference, or verbatim reproduction. • Verify thresholds and criteria for acceptable memorization risk are defined and documented. • Confirm retraining, fine-tuning, and reinforcement learning workflows include privacy guardrails and do not introduce new exposure risks. | F20: • Inspect training logs and review model training pipelines for indicators of memorization or overfitting. • Review memorization test results, extraction attempts, nearest-neighbor similarity analysis, and adversarial probing designed to detect resurfacing of personal data. • Validate that privacy checks were executed at training gates before model promotion. • Examine training hyperparameters (e.g., dropout, gradient clipping, DP settings) to ensure privacy-preserving methods were enabled when applicable. • Confirm remediation actions were taken when memorization signals appeared (e.g., dataset correction, retraining, applying stronger privacy techniques). | H20: 3 | I20: =G20*H20 -> 0
A21: Core Risk Theme | B21: 4.4 | C21: Inference & Output Risk | D21: Identify risks where AI model outputs may directly or indirectly reveal personal data, sensitive attributes, or enable inference attacks. Organizations shall evaluate all outputs—including text, images, embeddings, scores, and API responses—to detect privacy leakage, unintended re-identification, sensitive attribute inference, dataset reconstruction, or exposure of memorized content. Controls must prevent unauthorized inference pathways, enforce guardrails, and ensure continuous monitoring of output risks. Leakage thresholds must be defined, tested, and remediated when exceeded. | E21: • Execute output leakage tests including adversarial prompts, extraction attempts, attribute inference probes, membership inference tests, and similarity-based reconstruction attempts. • Inspect guardrail filters, redaction layers, and output sanitization rules to verify they block personal or sensitive data leakage. • Review monitoring dashboards to confirm alerts are generated when suspicious outputs occur. • Validate that inference pipelines capture logs needed for audit and investigation. • Confirm remediation steps (e.g., tightening filters, retraining, dataset correction) occur when leakage is detected. | F21: • Output logs showing inference patterns • Red-team and adversarial test reports • Leakage detection results (membership inference, attribute inference, reconstruction tests) • Guardrail and policy enforcement logs • Monitoring dashboards and alert records • Evidence of remediation actions when leakage occurred | I21: =G21*H21 -> 0
A22: Core Risk Theme | B22: 4.5 | C22: Profiling & Automated Decision-Making (ADM) Risk | D22: Identify risks where AI-driven profiling or automated decision-making (ADM) impacts individuals. The organization shall assess how personal or inferable attributes contribute to profiling outputs, eligibility decisions, risk scoring, prioritization, or automated classification. ADM workflows must document decision logic, safeguards, privacy controls, human oversight, and user rights such as explanation, contestability, and opt-out mechanisms. Profiling activities must align with legal restrictions and be monitored to detect bias, unfair treatment, or unintended consequences. | E22: • Review profiling workflows to determine how personal data influences decisions. • Inspect decision trees, scoring models, or logic to confirm transparency and compliance with legal requirements (e.g., GDPR Art. 22-like safeguards). • Validate that ADM outputs include risk checks for discriminatory or unintended impacts. • Evaluate human-in-the-loop controls and override mechanisms. • Confirm documentation of user rights such as notification, explanation, or contest processes. • Test sample profiling outputs for accuracy, fairness, and privacy leakage risks. | F22: • Profiling logs showing inputs, outputs, and decision factors • ADM governance documentation (decision logic, safeguards, overrides) • User notification and explanation templates • Risk assessments for ADM processes • Bias/fairness evaluation reports • Evidence of human-review checkpoints and override logs | H22: 3 | I22: =G22*H22 -> 0
A23: Core Risk Theme | B23: 4.6 | C23: Data Storage & Retention Risk | D23: Identify risks in storing and retaining AI datasets. The organization shall define and apply retention periods for AI training, validation, and inference datasets; ensure secure storage of personal and sensitive data; enforce access controls; maintain deletion, archival, and minimization procedures; and confirm that storage locations comply with legal, regulatory, and contractual obligations. Retention must reflect purpose limitation, data minimization, and deletion-on-expiry requirements. | E23: • Review documented retention schedules for AI datasets, including training data, model artifacts, logs, and derived datasets. • Inspect storage architecture to confirm secure storage (encryption, access control, zoning). • Validate retention policy alignment with legal requirements (e.g., GDPR data minimization, sector rules). • Test deletion workflows by sampling records scheduled for deletion and confirming they were securely removed. • Review archival processes and verify restricted access to archived data. • Examine monitoring mechanisms for unauthorized data retention or unapproved storage locations. | F23: • Storage system logs • Retention schedules • Deletion and archival records • Access control logs • Encryption and storage configuration records • Data minimization assessments • Evidence of secure wipe procedures | H23: 3 | I23: =G23*H23 -> 0
A24: Core Risk Theme | B24: 4.7 | C24: Third-Party & Supply Chain Risk | D24: Identify privacy risks from vendors or external AI services. The organization shall assess third-party providers involved in AI data processing; maintain current Data Processing Agreements (DPAs); ensure suppliers apply adequate privacy, security, and ethical AI controls; verify data sharing, transfer, and access arrangements; conduct periodic vendor risk assessments; and monitor ongoing supplier compliance. | E24: • Review third-party risk assessment records for AI-related vendors, including SaaS, external APIs, cloud providers, labeling vendors, or model-hosting services. • Check that DPAs include privacy protections, data handling obligations, retention limits, cross-border transfer clauses, and AI-specific requirements. • Evaluate supplier onboarding workflows, including due-diligence scoring and approval gates. • Inspect monitoring processes for ongoing supplier compliance (e.g., annual reassessments, security questionnaires, SOC reports). • Verify escalation steps for suppliers failing privacy requirements. • Confirm that high-risk vendors receive enhanced oversight or remediation plans. | F24: • Supplier audit reports • Vendor risk assessment records • DPAs and contract clauses • Due-diligence questionnaires • SOC 2/SOC 3 reports • Ongoing monitoring logs • Supplier remediation or exception approvals | H24: 3 | I24: =G24*H24 -> 0
A25: Core Risk Theme | B25: 4.8 | C25: Monitoring, Drift & Operational Risk | D25: Identify risks from changes in AI behavior over time. | E25: • Review the organization's drift monitoring framework to confirm continuous tracking of model performance, data distribution changes, and behavioral deviations. • Inspect drift detection methods (statistical drift tests, distribution comparisons, concept drift detectors, operational telemetry, trigger thresholds). • Verify monitoring frequency, automated alert workflows, and documented response steps. • Check sample drift alerts to ensure they were routed, analyzed, and closed. • Confirm retraining, recalibration, or model rollback actions where drift thresholds were exceeded. • Validate that operational risks (e.g., degraded accuracy, harmful outputs, fairness shifts) are assessed and tied to remediation. | F25: • Drift detection reports • Monitoring dashboards/logs • Alert tickets and investigation notes • Retraining or model-update records • Operational risk assessments • Post-drift remediation documentation | H25: 3 | I25: =G25*H25 -> 0
A26: Core Risk Theme | B26: 4.9 | C26: Incident & Harm Risk | D26: Identify risks where AI causes privacy harm or incidents. | E26: • Review the incident management workflow to confirm processes for detecting, triaging, investigating, and documenting AI-related privacy harms. • Inspect incident intake channels (automated alerts, monitoring tools, internal reporting mechanisms) to verify that AI-specific risks are captured. • Validate classification of incidents (privacy harm, data misuse, unexpected model behavior, harmful outputs). • Examine a sample of incidents to confirm proper investigation steps, severity assessment, containment actions, and closure. • Check whether incidents triggered corrective actions, model updates, policy changes, user notifications, or retraining. • Verify risk assessments tied to incidents and whether recurring patterns were analyzed and mitigated. | F26: • Incident logs • Root-cause analysis reports • Harm assessment documents • Corrective action and remediation records • AI risk assessment updates • Lessons-learned summaries | H26: 3 | I26: =G26*H26 -> 0
A27: Core Risk Theme | B27: 4.1 | C27: Rights & Transparency Risk | D27: Identify risks related to DSARs, consent, and transparency. | E27: • Review DSAR handling processes to confirm intake, verification, response workflows, timelines, escalation paths, and communication steps. • Inspect logs for DSAR requests linked to AI systems, checking for completeness, timely closure, and appropriate disclosure of AI-related processing. • Validate consent collection, tracking, withdrawal, and enforcement mechanisms, especially where AI uses personal data for training, inference, or profiling. • Examine transparency notices to confirm clarity of AI processing, data sources, intended use, automated decision-making, and user rights. • Cross-check whether rights requests (access, deletion, objection, restriction) trigger updates to AI models, datasets, or retention processes. • Assess whether recurring rights issues lead to improvements, such as updating notices, improving consent flows, or modifying model behaviors. | F27: • DSAR logs and response records • Consent records and withdrawal logs • Transparency notices and privacy policy excerpts referencing AI • Change-control documentation tied to rights requests • Communication templates for DSAR responses • Evidence of updates made due to DSAR trends | I27: =G27*H27 -> 0
A28: Governance | B28: A.1 | C28: AI Privacy Governance | D28: Assign roles and responsibilities for managing AI data privacy risks. | E28: • Review the AI governance structure to confirm defined roles for privacy, risk, legal, security, engineering, compliance, AI ethics, and model owners. • Verify that responsibilities include oversight across the AI lifecycle—data collection, training, deployment, monitoring, incident management, and rights handling. • Check whether a RACI or similar accountability framework is documented and communicated. • Interview role owners to ensure they understand duties, reporting lines, escalation responsibilities, and authority levels. • Confirm governance forums or committees exist, meet regularly, and review AI privacy risks, KPIs, incidents, and approvals. • Validate that governance responsibilities are updated when new AI systems, policies, or regulations are introduced. | F28: • AI Governance Policy • RACI matrix for AI privacy • Organizational chart reflecting reporting lines • Committee/working group charters • Meeting minutes or oversight reviews • Role assignment or designation records | H28: 3 | I28: =G28*H28 -> 0
A29: Governance | B29: A.2 | C29: AI Privacy Risk Register | D29: Maintain a risk register covering AI-specific privacy risks. | E29: • Review the organization’s AI privacy risk register to confirm that AI-specific risks are separately captured, not blended into general enterprise risks. • Check that risks include the full lifecycle (collection, preparation, training, inference, deployment, monitoring). • Confirm each risk entry contains likelihood, impact, risk owner, mitigation plan, and review cadence. • Validate that risks related to re-identification, leakage, model memorization, consent failures, transparency gaps, ADM risks, third-party exposure, and drift are included where applicable. • Check that treatment plans are assigned, tracked, and updated after mitigation is completed. • Verify that periodic risk register reviews are documented, and that new AI systems trigger updates to the register. | F29: • AI privacy risk register • Risk treatment plans • Risk review meeting minutes • Version history showing updates • Assigned risk owners and mitigation tracking | H29: 3 | I29: =G29*H29 -> 0
A30: Governance | B30: A.3 | C30: Regulatory Alignment | D30: Map applicable global privacy laws to AI data processing. | E30: • Review the organization's regulatory mapping to confirm global and local privacy laws relevant to AI systems (e.g., GDPR, CCPA, LGPD, PDPA, APPI, HIPAA, sector-specific rules) are explicitly included. • Verify that each AI dataset, data flow, and processing activity is mapped to the correct legal obligations, including lawful basis, processing limitations, retention rules, transparency, ADM requirements, and special category protections. • Check that the mapping covers all lifecycle stages (collection → training → inference → outputs → storage → sharing). • Confirm the regulatory mapping is reviewed periodically—especially after new AI use cases, new jurisdictions, or legislative updates. • Validate that DPIAs/PIAs incorporate regulatory references from the mapping. • Ensure that regulatory gaps identified in mapping have assigned mitigation actions. | F30: • Regulatory mapping matrix • AI system inventory with linked legal requirements • Lawful basis mapping • DPIA/PIA records • Jurisdictional applicability analysis • Version history of regulatory updates • Internal memos or compliance guidance documenting new regulatory interpretations | H30: 3 | I30: =G30*H30 -> 0
A31: Lawful Basis | B31: A.4 | C31: Lawful Basis for AI Data Use | D31: Document lawful grounds for using personal data in AI. | E31: • Review each dataset used by AI systems to confirm the lawful basis (e.g., consent, contract, legitimate interest, legal obligation, vital interest, public task) has been explicitly assigned and justified. • Confirm that lawful basis selection aligns with the type of data (personal, sensitive/special category, pseudonymized, derived, or inferable data). • Validate that consent—if used—is freely given, explicit where required, specific to AI processing, and traceable to data subjects. • Check that legitimate interest assessments (LIAs) and balancing tests are completed where applicable. • Verify that lawful basis documentation covers all lifecycle stages (collection → preparation → training → inference → outputs → retention). • Ensure updates occur when AI models change their purpose, inputs, or processing methods. | F31: • Lawful basis documentation per dataset • Consent records, logs, and version history • Legitimate interest assessments (LIAs) • Contractual purpose statements • DPIA/PIA references to lawful basis • Data inventory showing basis-to-dataset mapping • Records of lawful basis updates after model or data changes | H31: 3 | I31: =G31*H31 -> 0
A32: Lawful Basis | B32: A.5 | C32: Purpose Limitation | D32: Personal data used for AI must only be processed for clearly defined, documented, and approved purposes. The purpose must be specific, explicit, legitimate, and aligned with the organization’s AI governance framework. Any dataset used for AI must have a mapped purpose statement describing why the data is needed, how it will be used, whether it supports model training, inference, evaluation, or monitoring, and what limitations apply. The organization must ensure no repurposing or secondary use occurs unless formally reviewed and approved through governance (privacy, legal, AI governance). Purpose statements must be updated when AI models or datasets change, and must be embedded into dataset inventories, data flow diagrams, and model documentation to demonstrate compliance with purpose limitation obligations. | E32: • Validate dataset-to-purpose mapping for each dataset feeding into the AI system. • Inspect whether stated purposes match actual AI processing activities (training, testing, inference, monitoring). • Review governance workflows to confirm repurposing or secondary use requires formal approval. • Check model development documents, data specifications, data access logs, and feature engineering notes to ensure no undeclared or unauthorized use of personal data. • Confirm that purpose statements are specific, documented, and approved by appropriate governance functions (privacy, legal, data governance). • Verify periodic review and updates when AI system functionality, data sources, or processing purposes change. | F32: • Purpose limitation statements per dataset • AI model cards or design docs showing purpose alignment • Data inventory showing dataset-to-purpose mapping • Approval logs for secondary use requests or purpose changes • Data flow diagrams reflecting defined purposes • Governance approval emails or workflow records | H32: 3 | I32: =G32*H32 -> 0
