Workbook

Sheet Introduction
A1: INTRODUCTION & USER GUIDE
A3: AI Cybersecurity Maturity Assessment Tool
A5: BSI Digital Trust
A6: This workbook supports the assessment of an organization’s AI cybersecurity posture across multiple domains. It is designed to help assessors evaluate controls, assign maturity scores, and automatically generate risk-weighted domain scores and visual dashboards.
A7: Use this guide to understand how each sheet functions and how to complete the assessment properly.
A8: Note: The controls in this AI Cyber Security Framework were developed by taking into consideration the key requirements, principles, and best practices from globally recognized standards and guidelines, including ISO/IEC 42001 for AI management systems, ISO/IEC 27001 for information security, the NIST AI Risk Management Framework, NIST SP 800-53 Rev. 5 security and privacy controls, as well as the OWASP ML Security Top 10, OWASP LLM Top 10, and OWASP API Security Top 10. Elements of the EU AI Act were also considered to ensure alignment with emerging regulatory expectations. These sources collectively informed the structure, intent, and technical depth of the controls presented in this framework.
A10: Scoring Matrix
A11: This is where the assessor performs the actual assessment.
A13: How to Use This Sheet
A14: 1. Review each control requirement row-by-row.
A15: 2. Use the Test Procedure column to guide your evaluation.
A16: 3. Review and verify required Evidence.
... A111: Weight values should remain 3 unless the model is redesigned.

Sheet Scoring Matrix
A1: Domain | B1: Clause No. | C1: Clause Description | D1: Requirements Summary | E1: Test Procedure | F1: Evidence to Be Seen | G1: Maturity (0-5) | H1: Weight (3) | I1: Weighted Score (G*H) | J1: Comments/ Assessment Notes
A2: Domain 1 – Scope Requirements | B2: 1.1 | C2: AI Systems in Scope | D2: The organization shall identify all AI models, datasets, APIs, pipelines, and components. All AI systems shall be classified by cybersecurity risk, including AI-specific risks such as poisoning, adversarial manipulation, model extraction, drift, prompt injection, and supply chain vulnerabilities. System boundaries, dependencies, and owners must be defined. | E2: Identification & Completeness• Has the organization identified all AI models, datasets, APIs, pipelines, and LLMs?• Does the inventory include internal models, fine-tuned models, open-source models, embedded AI features, and vendor-supplied AI services?• Are any shadow/unapproved AI systems detected or acknowledged? Risk Classification• Has each AI system been classified by cybersecurity risk level (high/medium/low)?• Does the classification consider AI-specific risks: data poisoning, adversarial attacks, model inversion, membership inference, drift, model extraction, prompt injection, API misuse, supply chain exposure?• Is the risk classification tied to the organization’s AI risk assessment process? Boundaries & Dependencies• Are technical boundaries defined for each system (cloud, on-prem, hybrid, internal/external data sources)?• Are third-party AI components (OpenAI, Hugging Face, AWS Bedrock, etc.) included in the scope?• Are integration points where AI security risks originate clearly documented? Governance• Is a system owner assigned for each AI system?• Has leadership reviewed and approved the AI systems included in scope?• Are responsibilities for maintaining the inventory defined and active? | F2: • AI system inventory (full list of models, datasets, pipelines, APIs). • AI system risk classification register (showing AI-specific risks). • Architecture diagrams (data flow, model flow, dependency mapping). • AI cybersecurity risk assessment (covering poisoning, adversarial attack, inversion, extraction, drift, supply chain, prompt injection). • List of third-party AI services and open-source models. • Shadow AI identification logs (if applicable). • RACI matrix or ownership assignment table. • Management approval of scope/inventory. • Version-controlled history of inventory updates. | G2: 4 | H2: 3 | I2: =G2*H2 -> 12
A3: Domain 1 – Scope Requirements | B3: 1.2 | C3: AI Lifecycle Processes in Scope | D3: The organization shall define all applicable lifecycle stages for each AI system, including data collection, data preparation, model development, training, testing/validation, deployment, operation/inference, monitoring, maintenance, and decommissioning. Each lifecycle stage must consider AI-specific cybersecurity risks such as poisoning during data collection, adversarial testing risks, drift during operation, and pipeline compromise. Responsibilities for each stage must be clearly assigned. | E3: Lifecycle Identification• Has the organization documented all lifecycle stages for each AI system (data → model → deployment → monitoring → retirement)?• Are data collection and data preparation processes defined, including cybersecurity risk considerations?• Are training and testing pipelines described and secured?• Are deployment and inference environments formally defined?• Has the organization defined model retraining and update procedures?• Are decommissioning procedures documented and secure? AI Cybersecurity Risk Alignment• Does the lifecycle documentation address risks at each stage, such as:– Data poisoning during ingestion?– Adversarial attacks during model testing?– Tampering or unauthorized changes during deployment?– Drift or degradation during operation?– Model extraction or API abuse during inference?– Supply chain risks in training libraries or pre-trained models? Process Ownership & Responsibilities• Are owners assigned for each lifecycle stage (data owner, model owner, deployment owner, monitoring owner)?• Are responsibilities documented and communicated? Lifecycle Integration• Are lifecycle processes linked to risk assessment, monitoring, and incident response?• Are lifecycle changes reviewed and approved?• Are secure MLOps practices applied across the lifecycle (CI/CD, versioning, integrity checks)? | F3: • AI lifecycle documentation for each AI system.• Data flow diagrams and end-to-end model lifecycle diagrams. • SOPs for data collection, preparation, and labeling processes. • Training/testing pipeline documentation (including security reviews). • Deployment and release processes (CI/CD pipelines, approvals). • Monitoring procedures (drift detection, adversarial detection). • Model update/retraining logs and procedures. • Decommissioning policy for models and datasets.• Risk assessments linked to lifecycle stages. • Assignment of responsibilities (RACI for each lifecycle stage). • Version control logs showing lifecycle changes. • Security controls applied at each lifecycle stage (checks, reviews, approvals). | G3: 3 | H3: 3 | I3: =G3*H3 -> 9
A4: Domain 1 – Scope Requirements | B4: 1.3 | C4: Organizational and Technical Boundaries | D4: The organization shall define all organizational, system, and technical boundaries relevant to AI systems. Boundaries must cover internal vs. external responsibilities, cloud/on-prem/hybrid environments, third-party AI services, data sources, integration points, and infrastructure components. Cybersecurity risks resulting from unclear or unmanaged boundaries—such as API exposure, model extraction, data leakage, supply chain compromise, pipeline tampering, and access control gaps—must be identified and addressed. | E4: Boundary Identification• Have the boundaries of each AI system been clearly identified (infrastructure, network, application, data, APIs)?• Are the environments hosting AI (cloud, hybrid, on-prem) clearly documented?• Are AI data sources—internal, external, vendor-provided—identified?• Are integration points defined (APIs, services, applications, interfaces)?• Are external third-party AI components or models included in boundary mapping? Cybersecurity Risk Alignment• Have cybersecurity risks been identified for each boundary area:– Risks from external APIs (model extraction, brute force, probing)?– Risks from cloud or external hosting environments?– Risks from third-party model dependencies (supply chain)?– Risks from untrusted data sources (poisoning)?– Risks from integration points (prompt injection, adversarial input)?• Are controls mapped to each boundary to prevent unauthorized access, tampering, or data leakage? Responsibility Assignment• Are internal responsibilities vs. third-party responsibilities clearly defined (e.g., shared responsibility with cloud providers)?• Are system owners aware of their responsibilities for boundary security? Validation of Boundaries• Has the organization validated that defined boundaries match actual operational configurations?• Are boundary diagrams reviewed by security and AI governance teams? Changes & Review• Are boundary changes controlled, reviewed, and approved?• Are boundaries updated when integrations, models, or environments change? | F4: • AI system boundary documentation (internal/external boundaries). • System architecture diagrams (network, data flow, application flow). • Cloud environment diagrams and shared responsibility matrices. • List of third-party AI tools, APIs, and pre-trained models. • Inventory of integration points and external interfaces. • Security risk assessments mapped to boundary areas. • Access control and network segmentation diagrams. • Supplier or third-party service documentation (contracts/SLA). • Logs showing enforcement of boundary controls. • Governance approval records for boundary definitions. • Change control records for updates to architecture or boundaries. | G4: 5 | H4: 3 | I4: =G4*H4 -> 15
A5: Domain 1 – Scope Requirements | B5: 1.4 | C5: Internal and External Issues | D5: The organization shall identify internal and external issues that may impact the security of AI systems. Issues shall include regulatory obligations, emerging AI threat landscape, skills and resource limitations, supplier and technology dependencies, data quality challenges, and environmental factors. Identified issues must be reviewed periodically and incorporated into AI cybersecurity risk assessment. | E5: Identification of Issues• Have all internal issues affecting AI security been identified (skills, tooling, governance, data availability, infrastructure limitations)?• Have all external issues been identified (regulations, cloud dependency, vendor model risks, supply chain vulnerabilities, market conditions, emerging adversarial threats)? Alignment With AI Cybersecurity Risks• Do identified issues consider AI-specific risks: poisoning, adversarial attacks, drift, model extraction, model inversion, prompt injection, API abuse, supply chain compromise?• Are these issues integrated into the AI risk assessment? Regulatory & Compliance Considerations• Has the organization identified relevant AI, privacy, or security regulations and assessed their impact on AI systems?Technology & Environmental Factors• Are dependencies on external models, datasets, LLM APIs, GPUs/compute, MLOps tools identified?• Are rapid AI ecosystem changes or emerging vulnerabilities tracked? Monitoring & Review• Are issues reviewed periodically (quarterly/annually)?• Are changes documented, communicated, and reflected in risk assessments? | F5: • Internal and external issues register. • AI threat intelligence reports. • Regulatory and compliance mapping documents. • Supplier and third-party dependency assessments. • AI cybersecurity risk assessments linked to identified issues. • Governance meeting minutes. • Records of periodic review of issues. • Change logs updating identified issues. | G5: 3 | H5: 3 | I5: =G5*H5 -> 9
A6: Domain 1 – Scope Requirements | B6: 1.5 | C6: Interested Parties and Their Requirements | D6: The organization shall identify all relevant internal and external interested parties related to AI systems and determine their cybersecurity, privacy, safety, operational, and compliance requirements. These requirements must be documented, reviewed periodically, and incorporated into AI security governance and risk management processes. Interested parties shall include regulators, customers, users, business owners, IT/security teams, suppliers, and third-party AI service providers. | E6: Identification of Interested Parties• Has the organization identified all stakeholders involved in or affected by AI systems (regulators, users, customers, IT, security, data owners, suppliers, auditors)?• Are internal and external parties both included? Requirements Identification• Have stakeholder requirements regarding AI cybersecurity been documented?• Do requirements include expectations about: confidentiality, integrity, availability, robustness, explainability, safety, compliance, and acceptable risk levels?• Are AI-specific cybersecurity concerns captured for each stakeholder (e.g., model misuse, data leakage, prompt injection, adversarial threats)? Integration With AI Risk Management• Are stakeholder requirements integrated into AI risk assessment, control selection, and monitoring activities?• Do changes in stakeholder needs trigger updates to risk assessments and policies? Review & Maintenance• Are interested parties and their requirements reviewed periodically (e.g., annually)?• Is there evidence of updates when new regulations, contracts, or system changes occur? Communication• Are stakeholder requirements communicated to relevant teams responsible for AI development, deployment, and monitoring? | F6: • Interested party register. • Stakeholder requirement mapping (security, privacy, operational, regulatory). • Customer contracts or security addenda referencing AI expectations. • Regulatory requirement summaries (AI Act, NIST AI RMF, privacy laws, sector rules). • Supplier/third-party AI service agreements. • Risk assessment showing stakeholder requirement integration. • Governance meeting minutes documenting review of stakeholder requirements. • Communication logs or training materials related to stakeholder expectations. | G6: 4 | H6: 3 | I6: =G6*H6 -> 12
A7: Domain 2 – AI Security Objectives | B7: 2.1 | C7: AI Security Objectives – Protection of AI Assets | D7: The organization shall define documented AI security objectives to protect AI models, datasets, pipelines, APIs, and supporting infrastructure. Objectives must align with the organization’s AI risk assessment, cover confidentiality, integrity, availability, and robustness of AI systems, and address AI-specific threats such as poisoning, adversarial manipulation, model extraction, prompt injection, and drift. Objectives shall be measurable, monitored, and approved by management. | E7: Definition of Objectives• Have AI security objectives been formally defined and documented?• Do objectives explicitly address protection of AI assets (models, data, pipelines, APIs)? Coverage of Security Dimensions• Do objectives cover confidentiality, integrity, availability, robustness, and safe operation of AI systems? AI-Specific Threat Inclusion• Do objectives include protection against AI-specific risks such as data poisoning, adversarial attacks, prompt injection, model extraction, drift, model inversion, and supply chain risks? Alignment With Risk Assessment• Are AI security objectives directly linked to identified risks in the AI risk assessment? Measurability & Monitoring• Are objectives measurable and supported by KPIs or performance indicators?• Are progress and achievement of objectives monitored regularly? Approval & Review• Are objectives approved by senior leadership?• Are they reviewed and updated periodically? | F7: • Documented AI security objectives. • Mapping between objectives and identified AI risks. • KPIs or metrics measuring AI security performance. • Minutes or approvals from management/governance bodies. • Dashboards or monitoring reports showing tracking of objectives. • Revision history of objectives. • Evidence showing objectives are communicated to relevant teams. | G7: 0 | H7: 3 | I7: =G7*H7 -> 0
A8: Domain 2 – AI Security Objectives | B8: 2.2 | C8: Confidentiality, Integrity, and Availability (CIA) Requirements for AI Systems | D8: The organization shall define CIA requirements specifically for AI models, datasets, pipelines, APIs, and supporting infrastructure. CIA requirements must reflect the sensitivity of training data, model IP protection, operational reliability, and exposure to AI-specific cybersecurity threats such as model tampering, data poisoning, adversarial manipulation, model extraction, unauthorized access, and inference abuse. CIA requirements shall be documented, measurable, and reviewed regularly. | E8: Definition of CIA Requirements• Have confidentiality, integrity, and availability requirements been defined for each AI system (models, datasets, pipelines, APIs)?• Are CIA requirements based on data sensitivity, model criticality, and business impact? Confidentiality Considerations• Do requirements address prevention of data leakage, model inversion, membership inference, prompt injection, and unauthorized access to models or datasets? Integrity Considerations• Are requirements defined to protect models and data from poisoning, tampering, adversarial manipulation, unauthorized changes, or pipeline compromise? Availability Considerations• Do requirements ensure availability of AI inference, training pipelines, and model hosting environments?• Are risks such as inference DoS attacks, compute resource exhaustion, and cloud dependency addressed? Alignment With Risk Assessment• Are CIA requirements tied directly to AI risk assessment results? Review & Approval• Are requirements approved by AI governance or senior management?• Are CIA requirements reviewed periodically and updated when system risk changes? | F8: • Documented CIA requirements for each AI system. • Mapping of CIA requirements to asset sensitivity and risk levels. • AI cybersecurity risk assessment supporting CIA definitions. • Access control requirements and IAM documentation. • Integrity check processes (hashing, versioning, signatures). • Availability requirements (SLAs, redundancy, failover plans). • Governance approvals of CIA requirements. • Review and update records for CIA requirements. | G8: 2 | H8: 3 | I8: =G8*H8 -> 6
A9: Domain 2 – AI Security Objectives | B9: 2.3 | C9: Mitigation of AI-Specific Threats | D9: The organization shall define security objectives that explicitly address mitigation of AI-specific cybersecurity threats. These objectives must cover data poisoning, adversarial inputs, model evasion attacks, model inversion, membership inference, model extraction, LLM prompt injection, API abuse, drift-induced vulnerabilities, and supply chain risks affecting models, datasets, and pipelines. Objectives shall be linked to controls and risk treatments. | E9: Definition of Threat-Focused Objectives• Have AI security objectives been defined to address specific AI cybersecurity threats (poisoning, adversarial attacks, model evasion, extraction, inversion, prompt injection, etc.)?• Do objectives include preventive, detective, and corrective capabilities?Risk Alignment• Are threat-mitigation objectives tied to the AI risk assessment and risk treatment plans?• Do objectives reflect the risk level and exposure of each AI system (public-facing API vs internal pipeline, LLM vs classifier)?Coverage of AI Threat Categories• Do objectives cover the following categories:– Data integrity threats (poisoning, tampering)?– Model integrity threats (evasion, adversarial perturbations)?– Model confidentiality threats (extraction, inversion, inference)?– LLM-specific threats (prompt injection, jailbreak attempts)?– Pipeline/supply chain attacks (malicious components, compromised libraries)?– Drift-related vulnerabilities (concept drift, data drift)?Control Linkage• Are objectives mapped to controls in Annex A (monitoring, hardening, access control, model validation, incident response)?Review & Approval• Are objectives approved by relevant governance bodies?• Are threat-mitigation objectives updated when new AI threats emerge? | F9: • Documented AI threat-mitigation objectives.• AI risk assessment identifying AI-specific cybersecurity threats.• Mapping of objectives to AI risks and Annex A controls.• Threat intelligence reports considered during objective setting.• Governance meeting minutes approving objectives.• Records showing periodic review and updates of objectives.• Evidence of monitoring and metrics related to threat mitigation (drift alerts, adversarial detection logs, API security logs). | G9: 1 | H9: 3 | I9: =G9*H9 -> 3
A10: Domain 2 – AI Security Objectives | B10: 2.4 | C10: Lifecycle Security Integration | D10: The organization shall ensure that AI security objectives are applied consistently across every stage of the AI lifecycle, including data collection, preparation, model development, training, testing, deployment, inference, monitoring, maintenance, and decommissioning. AI-specific cybersecurity threats—such as poisoning during data ingestion, adversarial risk during testing, tampering during deployment, drift during operation, and supply chain risks—must be addressed at the appropriate lifecycle stage. Responsibilities for implementing controls shall be clearly assigned. | E10: Lifecycle Security Mapping• Has the organization mapped AI security objectives to each lifecycle stage (data → model → deployment → monitoring → retirement)?• Are the lifecycle stages documented and aligned with actual operational practices?Coverage of AI-Specific Threats by Lifecycle Stage• Does the lifecycle address:– Data poisoning & integrity threats during data collection and preparation?– Adversarial and robustness testing during model evaluation?– Model tampering, supply chain compromise, and unauthorized changes during deployment?– Drift, evasion, inference abuse, and model extraction threats during operation?– Secure archival or destruction of models/data during decommissioning?Integration with Controls and Risk Management• Are lifecycle security activities integrated with risk assessment, monitoring, and incident response?• Does the organization update lifecycle security controls when risks change?Responsibility Assignment• Are owners assigned for each lifecycle stage (data owners, model owners, pipeline engineers, security teams)?• Are roles and responsibilities documented and communicated?Review & Maintenance• Are lifecycle security activities reviewed periodically and updated as technology, threats, or processes evolve? | F10: • AI lifecycle documentation covering all stages.• Mapping of lifecycle stages to AI security objectives.• SOPs for each lifecycle phase including security steps.• Threat modeling or risk assessments aligned with lifecycle stages.• Evidence of adversarial testing, drift monitoring, data validation, deployment approval, and integrity checks.• RACI or ownership matrix for lifecycle responsibilities.• Version-controlled updates to lifecycle documents.• Records showing periodic review and lifecycle updates. | G10: 1 | H10: 3 | I10: =G10*H10 -> 3
A11: Domain 2 – AI Security Objectives | B11: 2.5 | C11: Compliance & Trustworthiness Objectives | D11: The organization shall define AI security objectives that ensure compliance with applicable legal, regulatory, contractual, and internal requirements. Objectives shall also address trustworthiness dimensions, including transparency, reliability, robustness, explainability (as applicable), and safety. AI systems must meet expectations of regulators, customers, internal governance bodies, and external stakeholders. Objectives must be measurable, documented, reviewed periodically, and integrated into AI governance processes. | E11: Compliance Requirements Identification• Has the organization identified all regulatory, legal, and contractual requirements relevant to AI cybersecurity, privacy, safety, and operational use?• Have sector-specific AI requirements (finance, healthcare, critical infrastructure, government) been identified?Trustworthiness Requirements• Have trustworthiness expectations been defined, including transparency, reliability, robustness, safety, and explainability (as applicable)?• Do objectives consider the risks of misleading outputs, unsafe behavior, hallucinations, or unintended consequences in AI systems?Integration With AI Governance and Risk Management• Are compliance and trustworthiness objectives aligned with the AI risk assessment and treatment plans?• Are requirements integrated into design, development, deployment, monitoring, and incident response processes?Measurability & Monitoring• Are trust and compliance objectives measurable and supported by KPIs or defined performance indicators?• Are objectives monitored and reviewed by governance bodies?Periodic Review & Approval• Are objectives reviewed and updated as laws, regulations, standards, and business needs evolve?• Has senior management or AI governance committee approved these objectives? | F11: • Compliance requirement register (AI, privacy, security, sectoral rules).• Documented trustworthiness objectives.• Mapping of compliance/trust objectives to AI risk assessments and controls.• Contractual or regulatory requirement documentation (customer requirements, SLAs).• Governance meeting minutes approving objectives.• Performance dashboards or KPI logs monitoring trustworthiness measures.• Evidence of periodic reviews and updates to objectives.• Policies or SOPs reflecting compliance and trust requirements. | G11: 1 | H11: 3 | I11: =G11*H11 -> 3
A12: Domain 2 – AI Security Objectives | B12: 2.6 | C12: Measurable AI Security Goals and KPIs | D12: The organization shall ensure that AI security objectives are supported by measurable goals and KPIs. Metrics shall enable tracking of cybersecurity performance across AI models, datasets, pipelines, and APIs. KPIs must reflect AI-specific risks such as drift, adversarial attempts, poisoning indicators, model integrity failures, and inference abuse. Goals shall be reviewed, monitored, and used to drive continuous improvement. | E12: Definition of Metrics & KPIs• Have measurable goals been defined for each AI security objective?• Are KPIs established for monitoring AI security performance (e.g., number of drift alerts, adversarial detection rate, failed integrity checks, unusual inference patterns)?Coverage of AI-Specific Risk Indicators• Do KPIs include monitoring for AI-specific risks, such as:– Drift (concept/data drift alerts)– Adversarial input detection events– Data poisoning indicators– Model integrity or signature mismatches– API abuse or excessive inference calls– Prompt injection or LLM misuse attempts?Monitoring & Reporting• Are KPIs tracked on a defined schedule (daily/weekly/monthly)?• Are metrics reviewed by AI governance or security teams?• Are trends analyzed to detect degradation or emerging threats?Use of KPIs for Improvement• Are KPI results used to adjust security controls, update risk assessments, or modify processes?Review & Approval• Are KPIs and targets approved by management?• Are metrics reviewed periodically and updated to reflect new risks or system changes? | F12: • Documented AI security KPIs and measurable goals.• KPI dashboards or monitoring reports (drift logs, adversarial detection logs, anomaly alerts).• Model integrity verification reports.• API usage analytics showing rate limits and anomaly detection.• Trend analysis reports for security indicators.• Governance meeting minutes reviewing KPI performance.• Evidence of improvements initiated based on KPI trends.• Records showing periodic review and updates of KPIs. | G12: 2 | H12: 3 | I12: =G12*H12 -> 6
A13: Domain 3 – Performance Monitoring | B13: 3.1 | C13: Monitoring of AI Security Controls | D13: The organization shall monitor AI security controls to ensure they are functioning effectively across all AI lifecycle stages. Monitoring shall cover data pipelines, model behavior, system access, inference patterns, adversarial indicators, API usage, and environmental conditions. Monitoring must detect AI-specific cybersecurity threats such as data poisoning, drift, adversarial activity, model tampering, prompt injection, and inference abuse. Monitoring requirements shall be documented and reviewed periodically. | E13: Monitoring Coverage• Are all AI security controls being monitored (access controls, integrity checks, drift detection, adversarial detection, pipeline monitoring)?• Does monitoring include all AI lifecycle stages: data ingestion → training → testing → deployment → inference → drift and anomaly detection?AI-Specific Monitoring Questions• Is data monitored for poisoning indicators or quality anomalies?• Is model behavior monitored for:– Drift (concept or data drift)?– Adversarial responses?– Unexpected output patterns?– LLM hallucinations or unsafe outputs?• Are model integrity mechanisms (signatures, hashing) monitored for tampering?• Are APIs monitored for suspicious or abnormal inference traffic (model extraction attempts, rate overuse)?• Are LLM prompts monitored for prompt injection or jailbreak attempts?Alerting & Escalation• Do monitoring tools generate timely alerts for anomalous or malicious events?• Are alert thresholds appropriate for AI-specific threats?• Are alerts routed to responsible teams with defined escalation paths?Monitoring Process & Documentation• Are monitoring procedures documented and current?• Are monitoring logs reviewed regularly?• Has monitoring been tested for effectiveness?Review & Improvement• Are monitoring processes updated when new AI threats emerge?• Are metrics from monitoring used to update risk assessments? | F13: • Monitoring dashboards and logs (drift alerts, anomaly detection, adversarial detection).• Pipeline monitoring logs (data flow anomalies, unauthorized changes).• API monitoring reports (rate limits, anomalies, extraction attempts).• Model integrity verification logs (hash mismatch, signature checks).• LLM prompt monitoring/audit logs (prompt injection detection).• Alert configuration documentation (thresholds, routing rules).• Incident tickets triggered by monitoring alerts.• Monitoring SOPs and updated procedures.• Review logs from governance or security meetings.• Evidence of tuning/improvement of monitoring processes. | G13: 3 | H13: 3 | I13: =G13*H13 -> 9
... A23: Domain 4 – Risk Management | B23: 4.5 | C23: Risk Acceptance | D23: The organization shall formally accept AI cybersecurity risks that remain after treatment, provided those risks are within the organization’s defined risk appetite and tolerance. Acceptance must be justified, documented, approved by authorized roles, and periodically reviewed. AI-specific risks—such as drift, adversarial vulnerability, data exposure, or model misuse—may only be accepted if supported by business justification and residual risk assessments. | E23: Formal Acceptance Process• Is there a documented process for accepting AI-related residual risks?• Are acceptance criteria defined and aligned with organizational risk appetite?Residual Risk Evaluation• Does acceptance occur only after evaluating residual risk following treatment?• Are AI-specific risks clearly explained and quantified/qualified?Approval Requirements• Are accepted risks reviewed and approved by authorized management or the AI governance body?• Do higher-risk AI systems (e.g., healthcare, finance, safety-critical) require elevated approval levels?Documentation• Is each risk acceptance recorded with justification, impact analysis, and reasoning for acceptance?• Is the decision linked to the corresponding risk treatment plan?Periodic Review• Does the organization review accepted risks periodically?• Are risks reassessed when models, data, threats, or business context change?Prohibited Scenarios• Does the organization prohibit acceptance of AI risks that violate legal, regulatory, ethical, or safety requirements?Communication• Are relevant stakeholders notified about accepted risks affecting their areas? | F23: • Risk acceptance forms or records.• Residual risk assessment documentation.• Business justification statements for acceptance.• Approvals from authorized management or governance boards.• Mapping of accepted risks to treatment plans.• Logs of periodic reviews and reconsideration of accepted risks.• Updated risk register noting acceptance decisions.• Evidence of stakeholder communication regarding accepted risks.• Version-controlled documentation showing changes to acceptance decisions over time. | G23: 3 | H23: 3 | I23: =G23*H23 -> 9
A24: DOMAIN 5 — DATA SECURITY & POISONING PROTECTION | B24: A.5.1 | C24: Data Validation & Sanitization | D24: The organization shall validate training, testing, and inference data for accuracy, completeness, consistency, and adversarial manipulation. Data sanitization controls must remove corrupted, anomalous, or malicious samples. Validation rules must be documented and consistently applied. | E24: • What mechanisms exist for validating datasets?• How does the organization detect corrupted, anomalous, or adversarial data?• Are validation rules defined and applied?• Are automated anomaly detection tools used prior to model training?• How are rejected or suspicious data samples handled?• Who validates and approves datasets? | F24: • Data validation SOPs• Data quality and anomaly detection reports• Data sanitization pipeline steps• Logs of rejected or flagged data• Dataset approval records | G24: 3 | H24: 3 | I24: =G24*H24 -> 9
A25: DOMAIN 5 — DATA SECURITY & POISONING PROTECTION | B25: A.5.2 | C25: Dataset Integrity Controls | D25: The organization shall protect datasets from unauthorized modification or tampering. Integrity verification must be applied using hashing, checksums, version control, and audit logs. Access to datasets must be restricted and monitored. | E25: • How is dataset integrity verified?• Are hashing or checksum mechanisms implemented?• Are datasets versioned throughout the lifecycle?• Who can modify datasets?• Are all dataset changes logged and reviewed? | F25: • Integrity verification logs• Hash or checksum records• Dataset versioning history• Access control lists• Dataset change logs | G25: 3 | H25: 3 | I25: =G25*H25 -> 9
A26: DOMAIN 5 — DATA SECURITY & POISONING PROTECTION | B26: A.5.3 | C26: Poisoning Detection & Monitoring | D26: The organization shall detect data poisoning attempts through monitoring of feature distributions, anomalies, outliers, and deviations from expected data patterns. Alerts shall be triggered for suspicious data behaviors. | E26: • Are feature distributions monitored for anomalies?• Are poisoning indicators defined?• Are sudden shifts in data flagged?• Are alerts generated and reviewed?• How are poisoning investigations conducted? | F26: • Poisoning detection logs• Feature distribution monitoring graphs• Drift or anomaly alerts• Incident investigation records• Data poisoning response SOP | G26: 3 | H26: 3 | I26: =G26*H26 -> 9
A27: DOMAIN 5 — DATA SECURITY & POISONING PROTECTION | B27: A.5.4 | C27: Secure Data Pipelines | D27: Data pipelines must be secured against interception, tampering, unauthorized access, and injection of malicious data. Controls include encryption, access control, integrity checks, and monitoring of pipeline components. | E27: • How is data protected during ingestion, transformation, and storage?• Are pipelines secured against tampering or modification?• How does the organization prevent malicious data injection?• Is encryption enforced (at rest/in transit)?• Are pipeline activities monitored? | F27: • Data pipeline diagrams• Encryption configuration• Pipeline access logs• Alerts for unauthorized changes• Secure CI/CD documentation | G27: 3 | H27: 3 | I27: =G27*H27 -> 9
A28: DOMAIN 5 — DATA SECURITY & POISONING PROTECTION | B28: A.5.5 | C28: Data Access Governance | D28: The organization shall enforce least privilege and role-based access control for all datasets. Sensitive data must have enhanced controls, including MFA, approval workflows, and periodic access reviews. | E28: • Who has access to training and inference data?• Is RBAC implemented for datasets?• Is MFA required to access sensitive data?• How often are access reviews performed?• Are dataset access logs monitored for abnormalities? | F28: • Dataset access control matrix• Access logs• MFA configurations• User access review records• Dataset access approval workflows | G28: 3 | H28: 3 | I28: =G28*H28 -> 9
A29: DOMAIN 6 — ADVERSARIAL & ROBUSTNESS CONTROLS | B29: A.6.1 | C29: Adversarial Input Detection | D29: The organization shall implement mechanisms to detect adversarial inputs designed to mislead or manipulate AI models. Systems shall monitor for unusual patterns, perturbations, and inputs intended to force misclassification or unsafe responses. Detection rules shall be defined for the specific model type (e.g., NLP, CV, tabular). | E29: • Are adversarial input detection mechanisms implemented?• How are anomalous or adversarial patterns identified?• Are detection thresholds documented?• Are alerts generated for adversarial signals?• Are adversarial attempts correlated with other security logs?• Does the organization retrain or adjust models based on adversarial findings? | F29: • Adversarial detection logs• Configured detection rules• Alert logs for adversarial attempts• Model behavior test reports• Documentation of adversarial investigations | G29: 3 | H29: 3 | I29: =G29*H29 -> 9
A30: DOMAIN 6 — ADVERSARIAL & ROBUSTNESS CONTROLS | B30: A.6.2 | C30: Adversarial Training / Model Hardening | D30: Models shall undergo adversarial robustness training or equivalent hardening techniques to reduce susceptibility to evasion attacks. Robustness methods may include adversarial augmentation, defense distillation, noise injection, and gradient masking where appropriate. | E30: • Has the organization applied adversarial training or robustness methods?• How were adversarial samples generated for testing?• Does the training pipeline include adversarial augmentation?• Are robustness improvements measured over time?• Who approves updated robustness requirements? | F30: • Adversarial training reports• Model robustness evaluation results• Documentation of adversarial augmentation methods• Change logs showing robustness updates• Approval records for robustness standards | G30: 3 | H30: 3 | I30: =G30*H30 -> 9
A31: DOMAIN 6 — ADVERSARIAL & ROBUSTNESS CONTROLS | B31: A.6.3 | C31: Model Robustness Testing | D31: Models shall be periodically tested to assess resilience against adversarial perturbations, manipulation, or regression failures. Testing shall align with ISO 24029-1/2 recommendations. Robustness tests shall include boundary tests, noise tests, perturbation tests, and stress testing for unexpected inputs. | E31: • Does the organization conduct scheduled robustness testing?• Are perturbation, noise, and boundary tests performed?• Are models tested under worst-case or edge-case conditions?• Are testing tools and methods documented?• Are results reviewed by AI governance or security teams?• Are robustness weaknesses fed back into risk assessments? | F31: • Robustness testing reports• ISO 24029-aligned evaluations• Stress test logs• Testing methodology documentation• Governance review minutes | G31: 3 | H31: 3 | I31: =G31*H31 -> 9
A32: DOMAIN 6 — ADVERSARIAL & ROBUSTNESS CONTROLS | B32: A.6.4 | C32: Evasion Attack Resistance | D32: The organization shall deploy controls to prevent attackers from crafting inputs that cause incorrect predictions or bypass detection. Controls may include input normalization, feature squeezing, model ensembling, or confidence-based detection mechanisms. | E32: • What protections exist to prevent evasion attacks?• Are input preprocessing or normalization controls implemented?• Does the organization use ensemble models or secondary verification systems?• Are confidence scores monitored for abnormal dips?• Are evasion attempts logged and escalated? | F32: • Logs of evasion detection• Configuration of normalization or preprocessing steps• Documentation of model ensembling or secondary verification• Incident reports for evasion attempts | G32: 3 | H32: 3 | I32: =G32*H32 -> 9
A33: DOMAIN 6 — ADVERSARIAL & ROBUSTNESS CONTROLS | B33: A.6.5 | C33: Output Monitoring for Abnormal Responses | D33: Model outputs shall be monitored to identify suspicious, unexpected, harmful, or adversarially influenced outcomes. Monitoring shall detect anomalies such as extreme misclassifications, sudden accuracy drops, LLM hallucinations, or output patterns matching known attack signatures. | E33: • Are model outputs continuously monitored for anomalies?• How does the organization detect harmful or manipulated responses?• Are output anomalies correlated with input anomalies?• Are thresholds set for unacceptable outputs?• Are output anomalies investigated and fed into retraining or tuning? | F33: • Output anomaly logs• Threshold and alert configuration• Correlation reports (input-output anomalies)• Hallucination detection logs (for LLMs)• Incident tickets for abnormal output behavior | G33: 3 | H33: 3 | I33: =G33*H33 -> 9
A34: DOMAIN 7 — MODEL INTEGRITY, SECURITY & GOVERNANCE | B34: A.7.1 | C34: Model Integrity Verification | D34: The organization shall ensure that AI models (weights, parameters, configuration files) are protected from unauthorized modification. Integrity must be validated using hashing, digital signatures, checksums, or cryptographic verification before deployment and periodically in production. | E34: • How is model integrity verified before deployment?• Are hashing or digital signature mechanisms in place?• Are integrity checks repeated during production use?• Are integrity failures logged and escalated?• Are model files stored securely to prevent tampering?• Is integrity verification integrated into CI/CD or MLOps? | F34: • Model hash/signature records• Integrity check logs (pre-deployment & runtime)• Evidence of CI/CD integrity gates• Incident tickets for integrity failures• Secure storage configuration documentation | G34: 3 | H34: 3 | I34: =G34*H34 -> 9
A35: DOMAIN 7 — MODEL INTEGRITY, SECURITY & GOVERNANCE | B35: A.7.2 | C35: Secure Model Storage & Registry Controls | D35: The organization shall use a secure model registry with controlled access, version tracking, audit logging, and tamper protection. Model artifacts must be stored with RBAC, MFA, encryption, and immutability controls where appropriate. | E35: • Is a secure model registry used?• Are model versions tracked systematically?• Who has access to model artifacts?• Are registry changes logged and reviewed?• Is MFA enforced for modifying model entries?• Are models encrypted at rest? | F35: • Model registry access logs• RBAC/MFA configuration settings• Model version history• Encryption configuration for storage systems• Change logs for model updates | G35: 3 | H35: 3 | I35: =G35*H35 -> 9
... A100: DOMAIN 16 — INCIDENT RESPONSE, RECOVERY & CONTINUITY FOR AI SYSTEMS | B100: A.16.6 | C100: Lessons Learned & Continuous Improvement | D100: After AI incidents, the organization must capture lessons learned and apply improvements to model design, datasets, pipelines, processes, and governance. | E100: • Are lessons learned workshops performed after AI incidents?• Are improvements tracked and implemented?• Are model updates triggered by incident findings?• Are governance committees reviewing lessons? | F100: • Lessons learned reports• Improvement tracking logs• Model update/retraining documents• Governance review minutes | G100: 4 | H100: 3 | I100: =G100*H100 -> 12

Sheet Domain Summary
A1: Domain | B1: Normalized Score (0–100)
A2: Domain 1 – Scope Requirements | B2: =SUMIF('Scoring Matrix'!$A:$A, A2, 'Scoring Matrix'!$I:$I) / (COUNTIF('Scoring Matrix'!$A:$A, A2) * 15) * 100 -> 76
A3: Domain 2 – AI Security Objectives | B3: =SUMIF('Scoring Matrix'!$A:$A, A3, 'Scoring Matrix'!$I:$I) / (COUNTIF('Scoring Matrix'!$A:$A, A3) * 15) * 100 -> 23.333333
A4: Domain 3 – Performance Monitoring | B4: =SUMIF('Scoring Matrix'!$A:$A, A4, 'Scoring Matrix'!$I:$I) / (COUNTIF('Scoring Matrix'!$A:$A, A4) * 15) * 100 -> 60
A5: Domain 4 – Risk Management | B5: =SUMIF('Scoring Matrix'!$A:$A, A5, 'Scoring Matrix'!$I:$I) / (COUNTIF('Scoring Matrix'!$A:$A, A5) * 15) * 100 -> 60
A6: DOMAIN 5 — DATA SECURITY & POISONING PROTECTION | B6: =SUMIF('Scoring Matrix'!$A:$A, A6, 'Scoring Matrix'!$I:$I) / (COUNTIF('Scoring Matrix'!$A:$A, A6) * 15) * 100 -> 60
A7: DOMAIN 6 — ADVERSARIAL & ROBUSTNESS CONTROLS | B7: =SUMIF('Scoring Matrix'!$A:$A, A7, 'Scoring Matrix'!$I:$I) / (COUNTIF('Scoring Matrix'!$A:$A, A7) * 15) * 100 -> 60
A8: DOMAIN 7 — MODEL INTEGRITY, SECURITY & GOVERNANCE | B8: =SUMIF('Scoring Matrix'!$A:$A, A8, 'Scoring Matrix'!$I:$I) / (COUNTIF('Scoring Matrix'!$A:$A, A8) * 15) * 100 -> 60
A9: DOMAIN 8 — API, INTERFACE & INFERENCE SECURITY | B9: =SUMIF('Scoring Matrix'!$A:$A, A9, 'Scoring Matrix'!$I:$I) / (COUNTIF('Scoring Matrix'!$A:$A, A9) * 15) * 100 -> 60
A10: DOMAIN 9 — INFRASTRUCTURE, ENVIRONMENT & ACCESS SECURITY | B10: =SUMIF('Scoring Matrix'!$A:$A, A10, 'Scoring Matrix'!$I:$I) / (COUNTIF('Scoring Matrix'!$A:$A, A10) * 15) * 100 -> 60
A11: DOMAIN 10— SUPPLY CHAIN & THIRD-PARTY AI SECURITY | B11: =SUMIF('Scoring Matrix'!$A:$A, A11, 'Scoring Matrix'!$I:$I) / (COUNTIF('Scoring Matrix'!$A:$A, A11) * 15) * 100 -> 60
A12: DOMAIN 11 — LLM & GENERATIVE AI SECURITY | B12: =SUMIF('Scoring Matrix'!$A:$A, A12, 'Scoring Matrix'!$I:$I) / (COUNTIF('Scoring Matrix'!$A:$A, A12) * 15) * 100 -> 60
A13: DOMAIN 12 — MONITORING, DETECTION & FORENSICS | B13: =SUMIF('Scoring Matrix'!$A:$A, A13, 'Scoring Matrix'!$I:$I) / (COUNTIF('Scoring Matrix'!$A:$A, A13) * 15) * 100 -> 60
... A17: DOMAIN 16 — INCIDENT RESPONSE, RECOVERY & CONTINUITY FOR AI SYSTEMS | B17: =SUMIF('Scoring Matrix'!$A:$A, A17, 'Scoring Matrix'!$I:$I) / (COUNTIF('Scoring Matrix'!$A:$A, A17) * 15) * 100 -> 80

Sheet Radar Data
A1: A | B1: B
A2: Domain | B2: Score
A3: Domain 1 – Scope Requirements | B3: ='Domain Summary'!B2 -> 76
A4: Domain 2 – AI Security Objectives | B4: ='Domain Summary'!B3 -> 23.333333
A5: Domain 3 – Performance Monitoring | B5: ='Domain Summary'!B4 -> 60
A6: Domain 4 – Risk Management | B6: ='Domain Summary'!B5 -> 60
A7: DOMAIN 5 — DATA SECURITY & POISONING PROTECTION | B7: ='Domain Summary'!B6 -> 60
A8: DOMAIN 6 — ADVERSARIAL & ROBUSTNESS CONTROLS | B8: ='Domain Summary'!B7 -> 60
A9: DOMAIN 7 — MODEL INTEGRITY, SECURITY & GOVERNANCE | B9: ='Domain Summary'!B8 -> 60
A10: DOMAIN 8 — API, INTERFACE & INFERENCE SECURITY | B10: ='Domain Summary'!B9 -> 60
A11: DOMAIN 9 — INFRASTRUCTURE, ENVIRONMENT & ACCESS SECURITY | B11: ='Domain Summary'!B10 -> 60
A12: DOMAIN 10— SUPPLY CHAIN & THIRD-PARTY AI SECURITY | B12: ='Domain Summary'!B11 -> 60
A13: DOMAIN 11 — LLM & GENERATIVE AI SECURITY | B13: ='Domain Summary'!B12 -> 60
A14: DOMAIN 12 — MONITORING, DETECTION & FORENSICS | B14: ='Domain Summary'!B13 -> 60
... A18: DOMAIN 16 — INCIDENT RESPONSE, RECOVERY & CONTINUITY FOR AI SYSTEMS | B18: ='Domain Summary'!B17 -> 80

Sheet Methodology
A2: Maturity Model | E2: Scoring Formula
A3: Maturity Level | B3: Name | C3: Description (Assessor Guidance) | E3: Weighted Score = Maturity × 3
A4: 0 | B4: Not Implemented | C4: No control exists. No evidence of planning, documentation, implementation, or responsibility. High-risk and unmanaged. | E4: Where: | F4: Maturity is from 0 to 5
A5: 1 | B5: Initial / Ad Hoc | C5: Control is informally in place but inconsistent, undocumented, or reactive. Highly dependent on individuals, not processes. No measurable effectiveness. | F5: 3 is the fixed weight you selected
A6: 2 | B6: Developing / Partially Implemented | C6: Control has been partially implemented. Some documentation exists, but implementation is inconsistent or incomplete. Monitoring or review is minimal. | E6: Maximum score per control = 15
A7: 3 | B7: Defined / Implemented | C7: Control is documented, consistently applied, and supported by assigned roles. Procedures exist and are followed. Some monitoring or periodic reviews occur.
A8: 4 | B8: Managed & Measured | C8: Control is monitored, measured, and evaluated for effectiveness. Metrics, logs, testing, or validation activities demonstrate consistent operation. Improvements are driven by results.
A9: 5 | B9: Optimized / Continuous Improvement | C9: Control is fully mature, automated where appropriate, and integrated into AI risk management. Continuous improvement processes exist. Considered best-in-class and risk-driven.
E10: DOMAIN SCORE → RISK LEVEL → COLOR CODE
E11: Domain Score % | F11: Maturity Level | G11: Risk Level | H11: Color
A12: Color Coding | E12: 0% – 20% | F12: Very Low | G12: Critical Risk | H12: Red
A13: Score Range | B13: Meaning | C13: Color | E13: 21% – 40% | F13: Low | G13: High Risk | H13: Orange
A14: 0–1 | B14: High Risk | C14: Red | E14: 41% – 60% | F14: Medium | G14: Moderate Risk | H14: Yellow
A15: 2 | B15: Medium Risk | C15: Orange | E15: 61% – 80% | F15: High | G15: Low Risk | H15: Light Green
A16: 3 | B16: Defined | C16: Yellow | E16: 81% – 100% | F16: Very High | G16: Minimal Risk | H16: Dark Green
A17: 4 | B17: Good | C17: Light Green
A18: 5 | B18: Best Practice | C18: Dark Green

Sheet Mapping
A1: Domain | B1: Clause No. | C1: Clause Description | D1: Requirement | E1: ISO/IEC 42001:2023 (Correct Mapping + Explanation) | F1: ISO/IEC 27001:2022 (Correct Mapping + Explanation) | G1: NIST AI RMF (Correct Mapping + Explanation) | H1: NIST SP 800-53 Rev 5 (Correct Mapping + Explanation)
A2: Domain 1 – Scope Requirements | B2: 1.1 | C2: AI Systems in Scope | D2: Identify all AI models, datasets, APIs, pipelines, components; classify AI systems by cybersecurity risk (poisoning, adversarial manipulation, model extraction, drift, prompt injection, supply chain risks). Define boundaries, dependencies, and owners. | E2: 4.1 – Context: Requires defining scope, system components, and relationships. 4.2 – Stakeholder needs: Includes expectations for security, integrity, and data usage. 6.1 – Risk actions: Requires identifying AI-specific risks. | F2: 4.1 – Organization context: Requires identifying internal/external factors defining system scope. 4.2 – Interested parties: Requires understanding stakeholder expectations related to AI system security. | G2: MAP 1.1 – Context: Requires inventory of AI systems and components. MAP 1.2 – Inventory: Direct alignment with identifying AI models, datasets, pipelines. MEASURE 1.1 – Risk ID: Includes adversarial, data, and model risks. | H2: RA-3 – Risk assessment: Requires identifying threats including adversarial AI risk. PM-5 – System categorization: Requires identifying system components and boundaries. SR-3 – Supply chain risk: Aligns with dependency assessment.
A3: Domain 1 – Scope Requirements | B3: 1.2 | C3: AI Lifecycle Processes in Scope | D3: Define lifecycle stages for AI systems (data collection → preparation → development → training → testing → deployment → inference → monitoring → maintenance → decommissioning). Include risks such as poisoning, adversarial testing, drift, pipeline compromise. Assign responsibilities. | E3: 4.1 – Context: Requires understanding processes and lifecycle. 6.1 – Risk actions: Requires addressing risks at each lifecycle stage. 8.1 – Operational control: Requires managing lifecycle transitions and controls. | F3: 4.1 – Context: Requires identifying lifecycle-related internal/external issues. 4.2 – Interested parties: Requires understanding lifecycle-relevant expectations (regulators, customers). | G3: MAP 1.3 – System characteristics: Requires lifecycle documentation. MEASURE 1.1 – Risk ID: Requires risk identification at each lifecycle stage. MANAGE 3.1 – Risk treatment: Requires applying controls across lifecycle. | H3: SA-3 – System development lifecycle: Aligns with structured lifecycle definition. RA-3 – Risk assessment: Requires assessing lifecycle-specific risks. SI-7 – Software integrity: Aligns to model integrity during lifecycle.
A4: Domain 1 – Scope Requirements | B4: 1.3 | C4: Organizational and Technical Boundaries | D4: Define organizational, system, and technical boundaries (internal vs external responsibilities, cloud/on-prem/hybrid, third-party AI, data sources, integration points, infrastructure components). Identify risks arising from unclear boundaries (API exposure, model extraction, data leakage, supply chain attacks). | E4: 4.1 – Context: Requires defining organizational and system boundaries. 4.2 – Stakeholder needs: Includes obligations related to boundary protection and responsibilities. 6.1 – Risk actions: Requires assessing boundary-related AI risks. | F4: 4.1 – Context: Requires mapping internal/external issues shaping boundaries. 4.2 – Interested parties: Requires identifying responsibilities and obligations across boundaries. | G4: MAP 1.1 – Context: Requires identifying boundaries, dependencies, external parties. MAP 1.3 – System characteristics: Requires documenting architecture and interfaces. MEASURE 1.1 – Risk ID: Identifies risks from boundary weaknesses. | H4: PM-5 – System categorization: Requires defining system boundaries. SA-8 – Interface documentation: Matches boundary definition. SR-3 – Supply chain risk: Covers third-party AI and external infrastructure.
A5: Domain 1 – Scope Requirements | B5: 1.4 | C5: Internal and External Issues | D5: Identify internal/external issues impacting AI security: regulatory obligations, AI threat landscape, skills/resource limitations, supplier/technology dependencies, data quality challenges, environmental factors. Review periodically and integrate into AI cybersecurity risk assessment. | E5: 4.1 – Context: Requires identification of internal/external issues affecting AI systems. 4.2 – Stakeholder needs: Requires identifying regulatory, technological, and supplier requirements. 6.1 – Risk actions: Requires incorporating identified issues into risk assessments. | F5: 4.1 – Understanding the organization: Direct alignment with identifying internal/external issues. 4.2 – Interested parties: Requires determining regulatory and dependency-driven requirements affecting security. | G5: GOVERN 1.1 – Governance context: Requires identifying internal/external factors affecting AI risks. MAP 1.1 – Context ID: Requires evaluating environment, threats, constraints. MEASURE 1.1 – Risk ID: Requires including these issues in risk assessment. | H5: RA-3 – Risk assessment: Requires inclusion of internal/external issue analysis. PM-11 – Business context: Requires identifying operational/environmental constraints. SR-2/3 – Supply chain: Covers external technology dependencies.
A6: Domain 1 – Scope Requirements | B6: 1.5 | C6: Interested Parties and Their Requirements | D6: The organization shall identify all relevant internal and external interested parties related to AI systems and determine their cybersecurity, privacy, safety, operational, and compliance requirements. Requirements must be documented, reviewed periodically, and integrated into AI security governance and risk management processes. Interested parties include regulators, customers, users, business owners, IT/security teams, suppliers, and third-party AI service providers. | E6: 4.2 – Needs and expectations of stakeholders: Requires identifying parties and their security, safety, privacy, and compliance expectations. 4.1 – Organizational context: Requires understanding internal/external relationships influencing AI systems. 6.1 – Actions to address risks: Requires incorporating stakeholder requirements into AI risk management. | F6: 4.2 – Needs & expectations of interested parties: Requires identifying regulators, suppliers, users, and their security/privacy/compliance needs. 4.1 – Understanding context: Requires determining how organizational relationships impact information security requirements. | G6: GOVERN 1.1 – Governance context: Requires identifying stakeholders and understanding their expectations regarding risk, safety, security, and compliance. MAP 1.1 – Context understanding: Requires documenting stakeholder needs and constraints that influence AI system design and operation. | H6: PM-5 – System categorization/context: Requires identifying interested parties and their requirements. RA-3 – Risk assessment: Requires integrating stakeholder requirements into risk evaluation. SR-2/SR-3 – Supply chain risk: Applies to supplier and third-party AI provider requirements.
A7: Domain 2 – AI Security Objectives | B7: 2.1 | C7: AI Security Objectives – Protection of AI Assets | D7: The organization shall define documented AI security objectives to protect AI models, datasets, pipelines, APIs, and supporting infrastructure. Objectives must align with the organization’s AI risk assessment, cover confidentiality, integrity, availability, and robustness of AI systems, and address AI-specific threats such as poisoning, adversarial manipulation, model extraction, prompt injection, and drift. Objectives shall be measurable, monitored, and approved by management. | E7: 6.2 – AI security objectives: Requires establishing measurable objectives aligned with AI risk assessment. 6.1 – Actions to address risks: Ensures objectives reflect AI-specific threats (poisoning, adversarial attacks). 9.1 – Monitoring: Requires monitoring achievement of objectives. | F7: 6.2 – Information security objectives: Requires documented, measurable objectives aligned with risk assessment. 5.1 – Leadership commitment: Requires objectives to be approved by management. | G7: GOVERN 2.1 – Policies and objectives: Requires setting security objectives for AI aligned to risk. MAP 1.3 – System characteristics: Supports defining CIA/robustness needs of AI assets. MEASURE 1.1 – Risk identification: Ensures objectives consider identified threats (drift, poisoning). | H7: PL-2 – System security objectives: Requires defining measurable security goals. RA-3 – Risk assessment: Objectives must reflect identified risks. SI-7 – Software/system integrity: Supports objectives for model integrity and robustness. PM-11 – Mission/business processes: Requires alignment of objectives to organizational context.
