Workbook

Sheet Requirement_Intent_Library
A1: Intent ID | B1: Intent Name | C1: Intent Description | D1: Intent Text | E1: Embeddings
A2: INT-01 | B2: ISMS Scope Definition | C2: The scope and boundaries of the management system are defined and maintained | D2: INT-01 ISMS Scope Definition. The scope and boundaries of the management system are defined and maintained | E2: -0.0029080636, 0.046388585, 0.05317602, -0.036230844, -0.008144918, -0.022527253, 0.025113499, -0.019437801, 0.036441486, 0.02977108, 0.053784546, -0.020385701, -0.041707598, -0.022480443, 0.042222507, 0.027009297, -0.019273967, 0.042316128, 0.0067289197, 0.024107086, 0.057248477, 0.050414234, -0.010087528, 0.050039757, 0.0003770389, -0.05181853, -0.058371913, 0.027571017, 0.030871112, -0.0096837925, 0.0464588, -0.033071175, 0.009256653, 0.0025394356, 0.04697371, 0.0066294484, -0.017974991, 0.014862135, -0.0076943734, 0.00495307, -0.040607568, -0.027009297, -0.0067757294, 0.006360292, -0.012697179, 0.022808112, 0.016652614, -0.0024897002, 0.029466817, 0.00696882, 0.03393716, -0.033679705, 0.0016412713, -0.032392435, 0.030449824, -0.0103157265, -0.016605804, 0.051865343, -0.02374431, 0.039086245, 0.015201507, -0.031128567, 0.02019846, 0.008753447, -0.02279641, -0.00976571, 0.007466175, 0.0022497997, 0.0026330554, -0.018759057, 0.0086364215, 0.037377685, -0.050039757, -0.0032152534, 0.025417762, -0.014487657, 0.008811959, 0.0374479, 0.02967746, 0.010666801, -0.0038852196, 0.04100545, 0.018782463, -0.015131292, -0.030332798, 0.0232294, -0.027664635, -0.007296489, -0.0122758895, 0.00701563, -0.05598461, 0.047652453, -0.021403816, 0.010561478, 0.025534786, -0.081355564, -0.029185956, 0.015728118, -0.054861173, -0.007828952, -0.007436919, -0.021836806, 0.026775248, -0.055235654, 0.040560756, -0.028554024, -0.015482366, -0.0058424575, -0.025792241, -0.03468612, -0.003768195, -0.023135781, 0.015447259, 0.04554601, 0.004640029, -0.047886502, -0.062350754, -0.0026169645, 0.024481565, 0.0000070054816, 0.025558192, 0.00433869, -0.042058673, -0.031268995, 0.00012918428, -0.00990614, -0.026424175, -0.011883857, -0.047980122, -0.0049735494, 0.044492785, -0.034873355, 0.04748862, -0.03730747, -0.007905018, 0.025277333, -0.0018124199, 0.025815645, -0.051022764, -0.032392435, -0.008220985, -0.034147803, 0.024575185, 0.058559153, 0.008220985, -0.020210164, -0.04327573, 0.031596664, 0.037050016, 0.0062257135, -0.0069278614, -0.015131292, -0.03194774, -0.022187881, 0.02967746, -0.009443892, -0.015728118, 0.018431388, 0.035154216, 0.0077762906, 0.033960566, 0.03227541, 0.0044147563, 0.0076709683, 0.033469062, 0.0062900768, 0.007559795, 0.019156942, -0.06431677, 0.01914524, -0.037588328, -0.010596585, -0.014382334, -0.019016512, 0.005503086, 0.0053655817, -0.008683232, -0.011567891, -0.009467297, -0.010403494, 0.055235654, 0.028273165, -0.03370311, -0.025277333, 0.013867426, -0.0073257457, -0.03255627, 0.005441648, 0.02294854, -0.002597948, -0.01692177, 0.065206155, 0.046388585, -0.011304585, 0.0014167301, -0.04262039, -0.0450311, 0.04355659, -0.028998718, -0.027898686, 0.010602437, -0.03815005, 0.06998076, 0.007267233, -0.04812055, 0.019121833, -0.02820295, 0.04081821, -0.033492465, -0.0070507373, -0.0058190525, -0.010198701, 0.036137223, 0.004274327, -0.012919526, 0.05266111, 0.03204136, 0.033258416, 0.054486696, -0.008180026, 0.03882879, -0.0109125525, 0.06047836, 0.016980283, -0.024715614, 0.08449183, -0.024481565, -0.006219862, -0.0063251844, -0.085147165, -0.0048506735, -0.029162552, -0.016582398, -0.023884738, -0.08074704, 0.0059975153, -0.041169286, -0.04919718, -0.029373197, -0.035856362, 0.018934594, 0.013001443, 0.021930426, -0.0099997595, -0.01303655, -0.0042684753, -0.012018436, 0.01497916, -0.06712536, 0.0063778455, 0.0055440445, 0.0015608168, -0.00021229009, -0.061976276, -0.010169446, -0.014967457, -0.011632254, 0.016746232, 0.015271721, 0.022585765, -0.05298878, -0.004806789, -0.0071619106, -0.0150025645, -0.044539597, 0.0150142675, 0.024481565, 0.018700546, 0.054720744, -0.043767232, -0.030005129, 0.0492908, 0.008560356, -0.031245591, -0.031011542, -0.0027252124, -0.016137704, 0.039811797, -0.051163193, -0.0122758895, 0.006962969, -0.06618916, 0.00071677624, 0.009116223, 0.003370311, -0.022035748, 0.018735653, 0.008431628, 0.029841295, -0.0002691568, -0.00050796027, 0.022152774, -0.019098429, -0.013212088, -0.018712247, -0.02644758, 0.0384075, 0.0049501443, 0.009537512, 0.039741583, 0.051865343, 0.066423215, -0.024481565, -0.020362295, -0.030075345, 0.037284065, -0.0023097747, -0.01602068, -0.017986694, -0.06015069, 0.019484611, -0.04905675, 0.010456156, -0.008180026, -0.007998638, -0.047886502, 0.012568451, 0.025722027, 0.0056815487, 0.0074018114, -0.01393764, 0.004601996, -0.013340814, -0.030449824, 0.02237512, 0.024200706, -0.01142161, 0.0128844185, 0.023709202, 0.024902854, 0.043416157, 0.018267553, 0.03162007, -0.03962456, -0.020491023, 0.012205675, -0.010327429, 0.025090093, -0.013375922, -0.041684195, 0.015037673, -0.04716095, -0.039999038, 0.028226355, 0.019566528, -0.0025730804, -0.087908946, -0.02290173, 0.09090478, -0.011714172, -0.011380651, -0.06506573, -0.008373116, 0.033211607, -0.050975952, -0.017787753, 0.05720167, -0.040584162, -0.008689083, 0.0076943734, -0.06717217, -0.017998397, 0.004309434, -0.011602998, -0.010707759, -0.023170888, 0.010268916, 0.009010901, -0.07840654, -0.011263627, 0.03915646, -0.010830635, -0.025417762, -0.022854922, -0.0236975, 0.037845783, 0.006512424, -0.011608849, -0.010783825, -0.0044059795, 0.06759346, 0.008291199, -0.000525514, 0.025113499, 0.05996345, 0.0058132014, -0.04020968, -0.026939083, -0.020502726, 0.020058032, -0.00057012966, 0.03536486, 0.017073901, 0.018209042, -0.022585765, -0.007214572, 0.009209843, 0.031198781, 0.066095546, -0.021298492, 0.06047836, 0.011497675, -0.05645271, -0.0042684753, -0.0530824, -0.015166399, -0.013001443, 0.028741263, -0.020561237, -0.012428022, -0.0062900768, -0.06029112, 0.027430587, 0.042222507, -0.021871913, -0.011503527, 0.03910965, 0.0049998797, 0.031128567, -0.0013830855, 0.0005072289, -0.028226355, -0.022574062, -0.036207438, 0.009502404, -0.003569253, -0.03426483, -0.026517794, 0.007261382, -0.05247387, 0.0012982426, 0.013528054, -0.0026345183, 0.021930426, -0.066235974, 0.018525008, 0.008847066, -0.037073422, 0.02195383, -0.022457037, 0.031549856, 0.002719361, -0.028905097, -0.03360949, 0.0068576466, 0.050507855, -0.032626484, 0.0062608207, 0.04863546, -0.028039115, 0.0125801535, -0.02602629, 0.03592658, -0.008191728, -0.01744838, 0.0034814845, -0.02094742, -0.036769155, -0.033164795, 0.003180146, -0.00094789994, 0.016652614, 0.0026228158, 0.042573582, 0.001284346, 0.030215774, -0.0053099953, -0.03536486, -0.020596346, -0.015564283, -0.043439563, 0.02290173, 0.030168964, -0.04915037, 0.025277333, -0.004838971, -0.023861334, 0.0092332475, -0.0030777494, 0.00067216053, 0.023334723, -0.023252806, -0.025909266, 0.01100032, 0.07358512, 0.07555114, -0.009648685, 0.012978038, 0.014417442, 0.012814203, -0.004300657, -0.023954954, 0.0052163755, -0.010614139, 0.008712488, -0.070355244, 0.013095062, -0.035622314, -0.03288394, 0.013446136, 0.02663482, 0.011883857, 0.027711445, 0.030168964, 0.046341777, 0.0058336807, -0.029630652, 0.021485733, -0.0077236295, -0.0056288876, -0.027149728, 0.043954473, 0.0005116173, 0.005263185, 0.01777605, -0.0275008, 0.039554343, 0.00025196877, 0.006986374, -0.026915679, 0.03859474, -0.04545239, 0.0023712127, 0.02810933, 0.0084901415, -0.020069733, -0.040420327, -0.10054761, -0.02184851, 0.0039027734, 0.0036189884, -0.01768243, 0.0122875925, 0.04587368, 0.006061879, 0.0058132014, 0.0021357005, -0.008133216, -0.006717217, 0.041216094, 0.012264187, -0.022597468, 0.05359731, -0.0055528213, -0.013329112, -0.0041631535, -0.020303784, 0.024387944, 0.014815326, 0.01768243, -0.000042147174, -0.030356204, 0.02616672, 0.006787432, 0.038992625, 0.010011462, 0.0024326507, -0.03503719, 0.0077821417, 0.011105643, -0.033632897, -0.047231164, 0.03213498, -0.00796353, 0.0011044205, -0.024083681, -0.0031450384, 0.029560436, -0.014312119, 0.0035399967, 0.009847627, 0.03023918, -0.048167363, 0.042550176, -0.019461205, -0.007706076, 0.012790798, -0.0048887064, 0.029373197, -0.016172811, 0.0050349873, -0.027383776, -0.011503527, -0.04498429, -0.006693812, 0.0384075, -0.040584162, 0.019742064, 0.0046429546, -0.012299295, 0.016196217, 0.00748958, 0.025768837, 0.0023112376, -0.0045902934, -0.025956076, 0.04332254, 0.018946297, -0.004686839, 0.034335043, 0.0122875925, -0.0011870692, 0.007618307, -0.04189484, -0.017542, 0.011883857, -0.030309394, -0.0036804264, 0.028858287, 0.018255852, 0.0033907904, 0.027102917, 0.0031596667, -0.00021320436, -0.0015812961, 0.011439163, -0.009759859, -0.0013728458, -0.0016339571, -0.002170808, -0.018548412, -0.013691888, -0.009490702, 0.00020515891, 0.04826098, 0.0069746715, -0.025230523, -0.033398844, -0.008215133, 0.028764669, 0.02469221, 0.0069278614, 0.043416157, -0.006740622, 0.003393716, 0.019086726, 0.0067289197, 0.0067055146, 0.0027720223, 0.0035282944, 0.05163129, 0.0031421129, 0.04840141, -0.050367426, 0.04725457, -0.0006853258, 0.0060267714, 0.0073784064, -0.02332302, 0.005312921, -0.022632575, -0.03138602, 0.0054884576, 0.033820134, 0.008203431, -0.014159987, 0.024996473, 0.008923132, -0.0054240944, 0.015154697, -0.026564604, 0.025441168, 0.012018436, 0.00068788574, 0.002941708, 0.008174174, -0.011181709, -0.009754008, -0.0066996636, 0.023311317, -0.013996152, 0.009291761, -0.012018436, 0.00053794787, 0.025207117, 0.002300998, 0.012966336, -0.014277012, 0.025043283, 0.021930426, 0.004961847, -0.009935396, -0.018501604, -0.02427092, -0.0078816125, -0.02299535, 0.042316128, -0.0010641932, 0.028507214, -0.008566207, 0.013282302, -0.022585765, 0.005005731, -0.009982206, 0.02105274, -0.025956076, 0.027688041, -0.0021064444, -0.020877205, -0.020584643, 0.013071657, 0.0034902613, -0.008987496, -0.018805867, -0.01768243, -0.005014508, 0.008946537, -0.021438923, 0.04072459, 0.01682815, -0.006998076, -0.0052544083, -0.01047371, 0.005134458, 0.019461205, -0.00616135, 0.020631453, -0.042831037, 0.01824415, -0.0067347707, -0.03290734, 0.003180146, -0.051022764, -0.022620872, 0.022655979, 0.028694453, 0.03777557, 0.016301539, 0.038430907, -0.015821738, -0.022667682, -0.0055820774, -0.0030426418, 0.0024326507, 0.007992786, 0.03379673, -0.035060596, -0.015189804, -0.021298492, 0.008016191, -0.029794486, 0.022433633, -0.06689131, 0.007735332, -0.00043189424, 0.00805715, -0.028600834, 0.01190141, 0.007413514, 0.030403014, -0.033305228, 0.007659266, 0.016289836, -0.0028480883, 0.038009617, 0.00839067, 0.014651491, 0.05298878, -0.009332719, -0.012053543, -0.009467297, 0.0001285443, -0.038547933, -0.021754889, -0.012919526, -0.004455715, -0.04697371, 0.027477397, 0.036418084, 0.041028857, -0.010122635, -0.0023785268, -0.054580316, -0.018185636, 0.00495307, 0.035294645, -0.013247195, -0.025324142, -0.023088971, -0.01403126, 0.023627285, -0.022702789, 0.0033264267, 0.010971065, -0.017120712, 0.026564604, -0.033492465, -0.038173452, 0.0062549696, -0.034545686, -0.010719461, 0.022129368, -0.010280618, -0.022550657, -0.006617746, -0.018712247, 0.015903655, -0.08964091, -0.0067347707, -0.008730042, 0.028717859, 0.015283424, -0.0031655177, 0.053363256, 0.0073374477, 0.024762424, -0.022527253, 0.008946537, 0.017120712, -0.0062257135, -0.00047248718, 0.014195095, -0.011602998, -0.0004918694, 0.036839373, -0.02289003, -0.009455595, 0.022773005, -0.031222187, -0.053644117, 0.054205835, 0.018501604, -0.008536951, -0.012790798, 0.00516664, -0.0016880811, -0.0014174615, 0.007922571, 0.02621353, -0.00701563, 0.03023918, 0.0027296008, -0.034569092, 0.0019206677, -0.011158304, 0.010222106, 0.016687721, -0.009022604, 0.016991984, -0.0041455994, 0.013282302, -0.016910067, -0.022059154, 0.016207919, 0.018478198, 0.008267794, 0.0052105244, -0.04379064, -0.0015257094, 0.016757935, 0.021930426, -0.0042538475, 0.009941247, -0.008969942, -0.026845463, -0.010350834, 0.0012704493, -0.01919205, -0.0005836606, -0.009871032, 0.010409346, -0.043111894, 0.017460084, 0.011485973, 0.008045447, 0.005862937, 0.02469221, 0.0031684435, -0.00041763185, -0.033305228, 0.041871432, 0.032930747, 0.010883296, -0.041122474, -0.004897483, 0.023077268, 0.022211285, -0.010087528, 0.04470343, 0.061133698, 0.022480443, 0.013434434, -0.032392435, -0.009894437, -0.036909588, -0.010643396, -0.012662071, 0.021766592, -0.004400128, 0.017249439, 0.023533665, -0.012334402, 0.0035721785, 0.009514107, -0.051163193, -0.0043825745, -0.010848189, -0.0020976674, 0.00046334462, 0.0048857806, -0.0550016, -0.008788554, 0.014440847, 0.0042977314, 0.01502597, 0.015985573, 0.04863546, 0.0077587366, -0.0019192048, 0.024832638, 0.03384354, -0.010327429, 0.031690285, 0.01569301, -0.019648446, -0.0078055467, 0.02441135, -0.0037798975, -0.002912452, -0.030730683, 0.013890831, -0.013785508, -0.0023024608, 0.009051859, -0.02047932, -0.008133216, -0.031105163, 0.0014606144, 0.008355563, -0.03180731, 0.008466736, -0.025066689, -0.00829705, 0.029373197, 0.021462327, -0.008472587, -0.029396601, 0.025300737, 0.028951908, 0.006576787, 0.044375762, -0.009736454, 0.040233087, -0.018115422, -0.014054665, 0.00053648505, 0.02839019, -0.027173132, -0.015061078, 0.0065884897, 0.006219862, -0.019367585, 0.027734851, -0.026962489, -0.017179225, 0.020806989, -0.0036657983, 0.01744838, 0.016090894, -0.050929144, 0.020970823, -0.014581276, 0.026751844, -0.01839628, 0.009935396, -0.032766912, -0.025090093, 0.027571017, -0.017588811, 0.00035820526, -0.009321016, 0.005798573, 0.015856845, 0.008431628, -0.006787432, 0.040654376, -0.042222507, 0.015669605, 0.010105082, -0.030590253, 0.0072204233, 0.022773005, 0.004335765, -0.016734531, -0.0047043925, -0.028764669, 0.038618147, 0.005386061, 0.0125918565, -0.009110372, -0.0075071338, -0.059588972, -0.021286791, 0.005778094, -0.0023814524, -0.0008316067, 0.002811518, -0.020537833, 0.026915679, -0.035060596, -0.009923694, 0.015798332, -0.019976115, 0.017155819, 0.007711927, -0.038711768, -0.0020567088, 0.01236951, -0.010339132, -0.012147162, -0.04641199, 0.007314043, -0.005669846, 0.017038794, -0.037611734, 0.0034258978, 0.014499359, 0.017120712, -0.01393764, 0.0053070695, 0.026330555, 0.0020742626, 0.039226674, -0.028483808, 0.0008316067, -0.005778094, -0.006190606, 0.026283745, 0.026190124, 0.004157302, -0.018068612, 0.0038910708, 0.008109811, 0.0035253686, -0.039718177, 0.013071657, 0.013633376, -0.008542802, 0.007232126, -0.04166079, -0.03393716, 0.06071241, -0.035013787, 0.028156139, 0.031549856, -0.012545046, -0.018466495, -0.009420487, 0.0131886825, -0.005263185, -0.04156717, 0.016722828, 0.025066689, 0.018127125, -0.026236935, -0.01128118, 0.022105964, 0.0038735173, -0.0023858408, 0.025066689, 0.02374431, -0.011017874, -0.018957999, 0.046388585, 0.049992945, 0.010374239, -0.006038474, -0.009438041, -0.000013325272, 0.03597339, -0.00053685077, 0.011831196, -0.012357807, -0.004294806, 0.0042275167, 0.025090093, -0.008759297, -0.018934594, 0.031151973, 0.027641231, -0.01511959, 0.008449183, 0.00089816446, 0.0005547702, -0.02071337, 0.005623036, -0.041824624, -0.020163354, 0.009274206, 0.00034558852, -0.019917602, 0.028437, 0.0052748877, 0.022655979, 0.0050934996, 0.045709845, 0.039554343, -0.035481885, -0.005672772, -0.04826098, 0.05982302, 0.005266111, 0.013305707, -0.011690767, -0.017705835, -0.025792241, -0.0101460405, 0.001432821, -0.02413049, 0.013949343, -0.003905699, 0.0011995031, 0.00957262, -0.017460084, 0.00197918, 0.016711125, 0.0070799934, 0.002529196, 0.015891952, 0.033773325, 0.02934979, -0.03403078, 0.018981405, 0.034826547, -0.008349711, -0.031081757, -0.01147427, -0.011240222, 0.012100353, -0.0067289197, -0.007530539, 0.015388747, 0.026424175, 0.01166151, -0.020970823, 0.011556188, -0.004809715, -0.030590253, -0.020701667, -0.018150529, -0.009724751, 0.012743988, -0.005564524, 0.009952949, -0.034147803, -0.0054621273, -0.0156462, 0.06815518, 0.00029804726, -0.0028334602, 0.007998638, 0.036745753, -0.0042596986, 0.00580735, -0.02379112, -0.01934418, 0.0051549375, 0.020233568, 0.022737896, -0.017272843, -0.012954633, -0.051350433, 0.0049852515, -0.024247516, 0.013212088, -0.017424976, -0.023674095, 0.006190606, -0.008455033, -0.031830713, -0.0068869027, 0.008595463, -0.002805667, -0.020970823, 0.0073667043, 0.03166688, -0.02787528, -0.029209362, 0.02565181, -0.030777493, 0.0053772843, 0.03019237, -0.041403335, 0.008964091, 0.021064444, 0.004066608, 0.01497916, 0.018571818, -0.011380651, 0.012615262, 0.0022717419, -0.01493235, -0.02478583, -0.031456236, -0.032088168, 0.0128727155, -0.027009297, -0.033469062, -0.008999199, 0.058793202, -0.007466175, -0.011345544, -0.0037798975, 0.0077528856, -0.0048506735, 0.0027705594, -0.021403816, -0.0044908226, -0.023182591, 0.021345302, -0.007208721, 0.011562039, 0.0065007214, 0.0142185, 0.01881757, 0.023662392, 0.027313562, 0.049618468, -0.0007826026, -0.0017319653, 0.020362295, -0.0022439484, 0.0049325908, -0.01213546, 0.0076358607, 0.01863033, 0.0246454, 0.010128487, 0.016676018, -0.015330234, 0.0074310675, 0.002077188, 0.021181468, -0.0013918624, -0.0028861214, -0.008004488, -0.023147482, 0.0017670728, -0.013106765, -0.028460404, -0.0023185515, 0.019075025, 0.003972988, 0.0009815446, -0.041777812, -0.0003883757, -0.017998397, 0.03204136, -0.030800898, 0.005769317, 0.030730683, -0.040443733, 0.0017773125, 0.029115742, 0.00030188714, -0.035762746, 0.00045091074, -0.029700866, 0.019484611, -0.034147803, 0.005939003, 0.016278135, -0.0051315324, 0.0035516992, 0.02108785, -0.006576787, -0.001467197, 0.018887784, -0.011509378, 0.0036892032, -0.037518114, -0.01654729, 0.047184356, 0.0012119369, -0.008888025, 0.045475792, 0.013680186, 0.023428343, 0.039694775, -0.0073374477, -0.031034946, 0.0015154697, 0.0065826387, 0.050788715, 0.021005932, 0.004531781, 0.00967209, -0.005418243, -0.024528375, -0.050554667, 0.011673213, 0.018279256, 0.025815645, 0.0017261142, 0.03477974, -0.006810837, 0.022503847, -0.00094424293, -0.0002731795, 0.0024853118, 0.012533344, -0.022258095, -0.037377685, 0.013212088, 0.05266111, 0.020455915, 0.04142674, -0.0109125525, 0.003063121, -0.026751844, 0.028881693, 0.020409105, -0.009754008, 0.012392915, 0.016324945, -0.01009923, -0.0018840975, -0.020467618, -0.066750884, 0.025394358, 0.02232831, -0.036113817, -0.016266432, -0.013013145, 0.006892754, 0.0006026771, -0.01872395, -0.006237416, -0.015681308, 0.00843748, -0.0037798975, 0.018665439, -0.02839019, 0.004072459, -0.004988177, 0.031971145, -0.0003752104, 0.009771561, -0.0029300055, -0.034522284, -0.002660849, 0.005579152, -0.018092018, 0.006939564, 0.031456236, 0.010350834, 0.00044981364, 0.024973068, -0.020455915, 0.00036204513, -0.014452549, -0.015587688, 0.0073315967, -0.015400449, -0.01502597, -0.0068517956, -0.0045522605, 0.0017027092, -0.016383456, -0.020128246, -0.016196217, -0.0037594181, 0.029279577, -0.006044325, -0.012966336, 0.021134658, -0.011538634, -0.028460404, -0.0041982606, -0.0023053864, -0.05659314, 0.012896121, -0.011673213, -0.0067347707, -0.011152453, 0.0017685356, -0.024973068, 0.0072028697, 0.017834563, -0.0041397484, -0.013516352, 0.036418084, 0.0062842257, 0.012018436, 0.005886342, -0.018583521, 0.0048799296, -0.010192851, -0.012334402, 0.0060033663, -0.049758896, 0.029396601, 0.0012675236, 0.03204136, -0.01734306, -0.0071033984, -0.014850433, 0.016734531, 0.038547933, 0.0043855, 0.0070448862, 0.03868836, -0.018466495, -0.021134658, -0.01502597, 0.012299295, 0.014897243, 0.017366463, 0.0074837287, 0.036137223, -0.013551459, 0.0016749159, 0.011597146, 0.011251924, 0.0073257457, 0.02658801, 0.00004210146, 0.011339692, -0.023826227, -0.025394358, -0.039133057, -0.0071560596, 0.04554601, 0.0060794326, 0.0038998476, 0.005280739, 0.018759057, 0.0027178985, -0.00594778, 0.013059955, -0.011796089, 0.007390109, -0.019929305, 0.007594902, 0.006313482, 0.046271563, -0.0076768193, -0.0006769147, -0.025066689, 0.009203992, -0.055048414, -0.0026637744, -0.008525249, -0.016793042, -0.011404056, 0.010134338, -0.010602437, -0.004882855, -0.028694453, 0.021977236, -0.039554343, 0.0027105843, 0.019695254, -0.023814524, -0.013633376, -0.0051520118, -0.03679256, 0.006547531, 0.030754087, -0.03023918, -0.04484386, 0.018969702, -0.013691888, 0.000882805, -0.0035634018, 0.025066689, -0.012486534, 0.021731485, 0.031549856, 0.0036804264, 0.001628106, 0.10887977, -0.021111254, 0.024926258, -0.014195095, 0.012193972, -0.025277333, 0.020221867, -0.0222815, -0.038173452, 0.0052690366, 0.014908945, 0.0134929465, -0.023908144, 0.03005194, -0.011450865, 0.00049808633, 0.027009297, -0.018384578, 0.038641553, -0.017857967, 0.0140897725, 0.017705835, 0.009104521, 0.031690285, 0.002002585, -0.050882336, -0.004388426, -0.001933833, -0.007852357, 0.03398397, 0.030988138, -0.0030075344, 0.034218017, 0.0009596024, 0.012030138, -0.019437801, -0.008607166, -0.0034785587, -0.0077821417, 0.02142722, 0.036745753, -0.0011914576, 0.022773005, 0.0050993506, 0.00092888344, 0.037588328, -0.037915997, 0.00061913376, 0.01772924, -0.041824624, -0.012217377, 0.026939083, 0.02061975, 0.011287031, -0.012310998, 0.018981405, 0.037752163, -0.0062900768, 0.026096506, 0.0062608207, 0.011210965, 0.01004657, 0.0019645519, -0.007319894, -0.00037923313 | F2: =LEN(E2)-LEN(SUBSTITUTE(E2,",",""))+1 -> 1536
A3: INT-02 | B3: ISMS Process Management | C3: ISMS processes are defined, implemented, maintained, and interact as intended | D3: ISMS Process Management. ISMS processes are defined, implemented, maintained, and interact as intended | E3: [ -0.031074971, 0.044978216, 0.047344208, -0.030782271, -0.0030626773, 0.0052076187, 0.029977346, -0.009951796, 0.047490556, 0.01420814, 0.06112549, -0.021562224, -0.028343106, -0.019037688, 0.014134965, -0.0041648755, -0.0053783604, 0.04258783, 0.003954497, 0.028440671, 0.05141761, 0.0394657, -0.028879723, 0.063857354, -0.0054362905, -0.029489513, -0.02812358, 0.012842207, -0.018488877, -0.038221728, 0.067613676, -0.023525752, 0.009707879, -0.04229513, 0.04066089, 0.026879605, -0.023391599, 0.015500898, -0.002347697, 0.037050925, -0.02914803, -0.003994134, -0.0201719, 0.020488992, 0.005042975, 0.046563674, 0.020708516, -0.027513789, 0.02797723, 0.008311457, 0.010860385, -0.023976998, 0.03434345, -0.013451999, 0.003548986, -0.025245365, 0.018671812, 0.026733255, -0.029391946, -0.000045948735, 0.0011357365, -0.026660081, 0.026294205, 0.021147566, -0.03768511, -0.0085614715, 0.0021571373, 0.006524768, -0.010805504, -0.042075608, -0.026001506, 0.049295537, -0.022574479, 0.022489108, 0.015513094, -0.020818278, -0.0119763035, 0.01406179, 0.049393106, 0.022281779, -0.054344613, 0.038343683, -0.014793539, -0.029977346, -0.051173694, 0.020476796, -0.042197566, -0.016732676, -0.0098420335, -0.0008224562, -0.03268482, 0.06590626, -0.0026602151, 0.010890875, 0.014464253, -0.083224334, -0.018110806, 0.015354548, -0.066491656, 0.022854982, -0.013317845, -0.044880647, -0.005914977, -0.0033508039, 0.038929082, -0.041612167, 0.00865294, -0.00684186, -0.035855737, -0.03136767, 0.031026188, -0.012573899, 0.0063723205, 0.049124796, 0.044856258, -0.030294437, -0.0400511, 0.022330562, 0.030953012, -0.0133666275, -0.000665816, 0.016952202, -0.04595388, -0.02873337, -0.015476506, -0.023342816, -0.014622798, -0.023976998, -0.03212381, -0.024098957, 0.005475927, 0.011262847, 0.066491656, -0.01906208, 0.01347639, 0.032879952, 0.04149021, 0.03166037, -0.0415146, -0.03905104, -0.018110806, -0.04810035, 0.019049885, 0.065711126, -0.012720249, -0.06600382, -0.077272765, 0.05195423, 0.0028736421, -0.05034438, -0.015830185, -0.0020107871, -0.002911754, -0.0030504817, 0.0038569306, -0.0044758692, -0.00001099292, 0.012537312, 0.036124043, 0.016330214, 0.03492885, -0.018427897, 0.012378766, 0.009043206, 0.00056748715, -0.0038782735, 0.00990911, 0.017757127, -0.05136883, 0.02148905, -0.01508624, -0.017025376, -0.033367787, -0.014147161, -0.0069394265, -0.021379286, -0.037319236, -0.03429467, -0.027660139, -0.0042776866, 0.024672162, -0.011439687, -0.04817352, -0.03695336, 0.018220568, 0.0029773067, -0.04695394, -0.015427723, 0.014378882, 0.0155740725, -0.015732618, 0.054588526, 0.061271843, 0.00824438, -0.012159241, -0.024830706, -0.035538644, 0.030416396, -0.03531912, 0.017244902, 0.000025654115, -0.053417727, 0.07049189, 0.006183285, -0.02885533, 0.040807243, -0.026513731, 0.013903244, -0.016098494, -0.00008313172, 0.018696206, 0.008152911, 0.03397758, -0.008902955, -0.0034300766, 0.05078343, -0.018781576, 0.05195423, 0.008957836, -0.018720597, -0.013903244, 0.017488819, 0.03178233, 0.023098899, -0.03283117, 0.12986118, -0.019940179, -0.009799348, -0.019830417, -0.0824438, -0.021464659, -0.0155374855, -0.018525463, -0.040148668, -0.061466977, 0.00027878903, -0.030270046, -0.03473372, -0.031099362, -0.022769611, -0.0043447637, 0.011049421, 0.030123696, -0.023672104, 0.009348103, 0.0012531214, 0.007811428, 0.034367844, -0.034684937, -0.030562745, 0.009146871, -0.016976593, 0.00086514157, -0.054637313, -0.017610775, -0.027001563, 0.013659328, 0.02590394, -0.02678204, 0.044587947, -0.032928735, -0.0013179117, -0.0044911136, -0.007030895, -0.0815657, 0.022184212, 0.008646842, 0.010890875, 0.020867063, -0.024684357, -0.03122132, 0.05444218, 0.020110922, 0.0019787732, -0.00897613, -0.040221844, -0.02268424, 0.02619664, -0.040099885, 0.025099015, 0.004616121, -0.06893082, 0.011823855, 0.0015077093, -0.0147203645, 0.016561935, 0.030099304, 0.0048021073, 0.01166531, 0.0024422146, -0.011482373, 0.021623204, -0.044539165, -0.0007069769, -0.009049305, -0.0048051565, 0.026172249, 0.014256923, 0.02297694, 0.015122827, 0.042612225, 0.07083337, -0.041099943, 0.010628665, -0.02722109, 0.018074218, -0.012671466, -0.03427028, 0.014452057, -0.023537949, -0.0053478708, -0.023806257, 0.029416338, -0.022354953, 0.03002613, -0.058539975, -0.017000984, 0.06429641, 0.01856205, -0.023025723, 0.031709153, -0.015964339, 0.01759858, -0.033026304, 0.040880416, 0.009311515, -0.020086529, -0.0038813225, 0.022001274, 0.011049421, 0.015781403, 0.016952202, 0.034514196, 0.0040795044, 0.027050348, -0.022903766, -0.023659907, 0.007384574, 0.0067320974, -0.001809556, -0.034123927, -0.05268598, -0.04375863, 0.0044911136, 0.0059424173, 0.01692781, -0.09307856, 0.0011799464, 0.05210058, 0.0051588356, 0.0394657, -0.03492885, -0.007165049, -0.0014535903, -0.02707474, 0.003981938, 0.06341831, -0.016122885, -0.010689643, 0.002312634, -0.050051678, 0.022647653, -0.014342294, 0.016720481, 0.005823508, -0.00019703885, -0.019074276, 0.0056344727, -0.07712642, -0.026025899, 0.021025607, 0.013147103, -0.0014596882, 0.031294495, -0.03963644, 0.032782387, 0.0027958937, 0.0011265896, 0.0021891512, 0.009970089, 0.07639467, 0.028806547, -0.004542946, 0.008902955, 0.023745278, 0.020257272, -0.003134328, -0.05136883, -0.0006597181, 0.025001448, 0.015549681, -0.006122306, -0.012573899, -0.009183459, -0.030050522, 0.0029422436, -0.009110284, 0.029635863, 0.02914803, -0.015403331, 0.040148668, -0.0053692134, -0.044295248, -0.015732618, -0.029977346, -0.010244496, -0.017818104, 0.0015557304, 0.01353737, -0.0060674245, 0.021354895, -0.07195539, 0.03875834, 0.014317903, -0.00011166805, -0.036270395, 0.026977172, 0.058881458, 0.037782677, 0.004549044, -0.01856205, -0.019245017, 0.010951854, -0.04814913, -0.008043149, -0.01362274, 0.0008910577, -0.03183111, -0.024037978, -0.037855852, -0.024416048, 0.043222018, 0.014842323, 0.011293337, -0.0736628, 0.0225135, -0.005829606, -0.07854114, 0.026708864, -0.024062369, 0.039075434, -0.048710138, -0.007524826, -0.039416917, -0.0059607113, 0.016586326, -0.047027115, 0.0016296676, 0.018452289, -0.051466394, -0.0037563152, -0.0005472878, 0.024940468, -0.00060445577, -0.026879605, -0.0187084, 0.012153143, -0.0009848131, 0.008439513, 0.028001621, -0.0030733487, -0.01648876, 0.038636383, 0.03990475, -0.0021678086, 0.045831922, 0.004420988, 0.0011464079, 0.03385562, -0.019391367, -0.019988963, 0.02178175, 0.03075788, -0.0421, -0.012817816, 0.0055887382, -0.02678204, 0.024672162, 0.0024071517, -0.0033325101, 0.0198792, 0.0014817931, -0.011823855, 0.039075434, 0.06034496, 0.054247044, -0.0060521797, -0.008299261, 0.005210668, 0.038807128, 0.0029986494, -0.0063052434, 0.030489571, -0.011805562, 0.007530924, -0.052539628, -0.0051009054, -0.024684357, -0.031245712, 0.012445843, 0.0062290193, 0.016025318, 0.028538238, 0.055173926, 0.08576106, 0.012409256, -0.019184038, 0.03839247, 0.00228062, -0.004963702, 0.018903535, 0.029952955, 0.03061153, -0.02230617, 0.0089883255, -0.0045002606, 0.01833033, 0.007671176, 0.020098725, 0.00570155, 0.0045856317, -0.008341947, 0.004481967, 0.023294032, -0.0026464947, -0.018744988, -0.045856316, -0.081273, -0.01833033, 0.0036587485, 0.0201719, -0.0154643105, 0.014574015, 0.015183806, 0.008555373, 0.0019589548, 0.012256808, 0.0036526506, -0.033245828, 0.000032966847, 0.014086182, -0.005991201, 0.015074044, -0.0046313656, 0.0022181163, 0.002347697, 0.0019071227, 0.028221147, -0.008927346, 0.03990475, -0.0008971556, -0.02487949, 0.045588005, 0.015647247, 0.035465468, 0.009439571, -0.00023515082, -0.030416396, -0.00025077673, 0.01523259, -0.029123638, -0.055125143, 0.0017958357, -0.03136767, -0.0033690976, -0.0044392818, 0.018574247, 0.04339276, -0.018525463, 0.03341657, 0.016732676, 0.034684937, -0.031879894, 0.026538122, -0.01765956, 0.0015595416, -0.031465236, -0.023050116, -0.010585979, -0.003102314, -0.015171611, -0.03885591, -0.010177419, -0.032001853, -0.017793713, 0.053076245, -0.046149015, -0.003335559, 0.024672162, 0.01619606, 0.016330214, -0.009738369, 0.0412219, -0.0037929027, 0.023513557, -0.024550203, 0.032196987, 0.0064332993, -0.019037688, 0.0019879201, 0.005070416, -0.011153085, -0.020928042, -0.036904577, -0.0052076187, 0.027635748, -0.03002613, 0.02140368, 0.016866831, 0.018001042, -0.0023156828, 0.016098494, 0.03329461, -0.0080797365, -0.034538586, 0.015281373, 0.0015046604, 0.006463789, 0.0034605663, -0.008159009, -0.023367207, 0.0039514485, 0.007994366, -0.012323884, 0.021001216, 0.008610255, -0.023147682, -0.020818278, -0.026660081, -0.0040581618, 0.016708285, -0.030879838, 0.015598465, 0.00011862349, -0.010433531, 0.033538528, -0.0026175296, 0.023428187, -0.008171205, -0.0032837267, -0.010616468, -0.016476564, 0.030733489, -0.08717578, 0.043807417, 0.006835762, -0.0039392523, 0.015488702, -0.015964339, 0.015061848, -0.04978337, -0.02198908, 0.025391715, 0.021891512, 0.010781112, -0.031855505, -0.007049189, -0.001153268, 0.01981822, 0.012250709, -0.0070857764, 0.037026536, -0.01181166, 0.010018873, 0.014622798, 0.040075492, 0.011153085, -0.0062930477, 0.01684244, 0.017147334, -0.03709971, -0.002064144, 0.018208371, -0.02605029, 0.041978043, -0.015781403, -0.0007001168, -0.05112491, 0.015635053, 0.011671408, 0.012329983, -0.013671524, -0.027708922, 0.0058783893, -0.005186276, -0.020062137, 0.036465526, 0.008701724, -0.004052064, -0.03875834, 0.017830301, -0.016659502, 0.020367034, -0.013293453, 0.028196756, -0.026903998, 0.005189325, 0.022672044, -0.0017760175, -0.002917852, 0.019696264, -0.021184154, -0.005908879, -0.0062869494, -0.042148784, -0.028245538, 0.005393605, -0.0066528246, 0.042953707, 0.02736744, -0.007537022, -0.0013491635, -0.031270105, 0.019366976, 0.0017440035, 0.0012691284, 0.006463789, -0.007457749, 0.013134907, -0.0033721465, -0.006335733, 0.016671697, -0.04283175, -0.035587426, 0.009720075, 0.035465468, -0.00030794466, 0.023257446, 0.024708748, -0.020293858, -0.007524826, 0.014244728, -0.015330156, 0.0004485778, 0.027416222, 0.02722109, -0.027318656, -0.0021190252, -0.030245654, 0.00926883, -0.031806722, 0.0024635573, -0.050832212, -0.015342352, 0.012647074, -0.00920785, -0.04519774, 0.008396828, -0.0044606244, 0.012317787, -0.0228062, 0.008957836, 0.025269756, 0.00912248, 0.03434345, 0.0039362037, -0.0018202274, 0.017086355, -0.007835819, 0.00669551, -0.010512804, 0.0042776866, -0.0085065905, -0.01391544, -0.005488123, 0.0054271435, -0.050149247, 0.035880126, 0.01324467, 0.030977404, -0.008140716, 0.017854692, -0.04905162, -0.0111225955, 0.020708516, 0.041758515, -0.02207445, -0.057661876, 0.003134328, -0.025099015, -0.018952318, -0.024050174, -0.029367555, -0.002917852, -0.023513557, 0.02797723, -0.05361286, -0.0031190831, -0.01084819, -0.036050867, -0.026416164, 0.0382949, 0.014708169, -0.02423311, -0.012537312, -0.028879723, 0.028099189, -0.096249476, -0.012134849, -0.02724548, 0.03339218, 0.021562224, -0.008994424, 0.035758168, 0.031245712, 0.0075736092, -0.029221205, 0.0017272342, -0.009201753, -0.036343567, 0.026172249, 0.028977288, -0.0022303122, -0.012610487, 0.017330272, -0.015074044, 0.005414948, 0.02692839, -0.0216354, -0.029977346, 0.032001853, 0.016354606, 0.014866715, 0.0060704737, 0.025562456, 0.002809614, 0.0049606534, -0.0016571082, 0.024720944, 0.02111098, 0.003134328, 0.025708806, -0.0089883255, 0.007939484, -0.016427781, 0.014988673, 0.024928274, -0.016915614, 0.003978889, 0.0032166496, 0.03985597, -0.003131279, -0.0022882423, 0.008750507, -0.001981822, -0.006341831, -0.009512746, -0.04914919, -0.013415411, 0.020147508, 0.026147855, 0.0073479866, 0.031611588, -0.014488644, -0.009482256, -0.012756837, -0.021537833, -0.02230617, 0.010140832, 0.006835762, 0.004594778, 0.007976072, 0.010250594, 0.00027726454, 0.038221728, -0.0023644662, 0.013976419, 0.020488992, -0.0023995293, -0.035416685, 0.02856263, 0.037197277, -0.010537196, -0.040392585, -0.004536848, 0.0008910577, 0.005979005, -0.025001448, 0.028782155, 0.057661876, 0.017732734, -0.003019992, -0.038197335, -0.022635458, -0.004332568, 0.00021780988, 0.00025782743, 0.044539165, -0.026440555, -0.0072992034, 0.026001506, 0.010793308, 0.017635169, -0.008482198, -0.048222307, 0.017415643, 0.0024803267, -0.0068479576, 0.027904056, -0.016708285, -0.052734762, -0.019171841, -0.00976276, -0.009957894, 0.03414832, 0.015683835, 0.024416048, -0.0014444435, -0.013110516, 0.019257214, 0.027050348, 0.009756663, 0.01192752, -0.003552035, -0.022879373, -0.019415759, 0.024806315, -0.02873337, 0.009299319, -0.025269756, 0.012683662, -0.035684995, -0.012732445, -0.008756605, 0.0034697133, 0.005607032, -0.024977056, -0.016269235, 0.015842382, -0.033733662, 0.00669551, -0.02900168, -0.005463731, 0.020293858, 0.015159415, 0.010726231, -0.01952552, 0.033197045, 0.028099189, 0.007756547, 0.034123927, -0.03400197, -0.0009840509, -0.031148145, 0.0022608016, -0.0042319526, 0.0070857764, -0.0071284617, -0.0008765752, 0.02297694, 0.010622567, -0.022708632, 0.024659965, -0.040977985, -0.0057899696, 0.039221786, 0.004777716, 0.022903766, 0.017793713, -0.037441194, 0.0019132206, -0.018366918, 0.01914745, -0.044978216, -0.01715953, -0.0037807068, 0.002265375, -0.0049941917, -0.0018720597, -0.022964746, -0.015622856, 0.01508624, -0.0088785635, 0.015683835, -0.042270742, 0.02172077, -0.011250651, -0.002494047, 0.03914861, 0.0006501901, 0.054637313, 0.008817584, 0.011890933, 0.0027120474, 0.010189614, -0.045270916, 0.01654974, -0.002748635, 0.039977927, 0.011348219, 0.030001737, -0.045758747, -0.012293395, 0.02090365, -0.006823566, -0.011348219, 0.011817758, -0.019696264, 0.01692781, -0.041636556, -0.009543235, 0.024257503, -0.019488934, 0.008378535, -0.0016982692, -0.04671002, -0.0093968855, 0.0045246524, 0.028147971, -0.011823855, -0.015183806, -0.013012949, -0.03329461, -0.012464137, -0.06034496, 0.031294495, 0.0061649913, 0.0081163235, -0.0049332124, -0.0018751086, 0.033319004, 0.0039453506, 0.019806026, -0.05873511, -0.005607032, -0.011707995, 0.017793713, 0.027635748, 0.031733546, 0.014244728, -0.015183806, 0.028977288, 0.020806083, -0.002583991, -0.03002613, 0.045807533, -0.0049515064, -0.0146106025, 0.030050522, -0.022037862, -0.040977985, 0.03368488, -0.052051798, 0.029269988, 0.03985597, 0.019952375, -0.014476448, -0.029513905, 0.010506706, -0.012573899, -0.020476796, 0.029196814, 0.017183922, -0.024013586, -0.014817932, -0.00669551, 0.014195944, 0.00088800874, -0.0005396654, 0.03817294, 0.024977056, -0.0073967697, -0.015842382, 0.01722051, 0.020074334, 0.0029422436, -0.01765956, 0.006049131, -0.036733836, 0.028147971, -0.010061558, 0.022635458, -0.011262847, -0.009244438, -0.0036465528, 0.018062022, -0.03046518, -0.028928505, 0.045758747, 0.012226318, -0.0045978273, 0.026269814, 0.007268714, -0.0053143324, -0.034831285, -0.020537775, -0.031977464, -0.020415816, 0.002707474, -0.01634241, -0.02856263, -0.0071284617, 0.013451999, -0.0022897667, 0.008640745, 0.033953186, 0.012793424, -0.03280678, 0.01809861, -0.024111154, 0.05200301, -0.011146987, 0.018196177, -0.0007607148, -0.019488934, -0.039368134, -0.03724606, -0.0023446481, -0.0062076766, -0.020184096, -0.0022547038, 0.00017159912, 0.028757764, -0.021757359, 0.007890701, 0.025245365, 0.001067135, -0.00961641, -0.003963644, 0.05566176, 0.008817584, -0.03827051, 0.02333062, 0.031684764, -0.018647421, -0.008433416, 0.015476506, 0.014659386, 0.012890991, -0.0032440904, -0.0154643105, 0.020013355, 0.02268424, -0.001631192, -0.012018989, -0.0011776597, -0.007622393, -0.014464253, -0.027343048, -0.018110806, -0.017927868, 0.031001795, -0.0033294612, 0.0155740725, -0.010262789, 0.005396654, -0.045758747, 0.069369875, -0.016525347, 0.010525, -0.00056939275, 0.040977985, 0.011933618, 0.01295197, -0.01055549, -0.01684244, -0.00950055, 0.00044781558, -0.0023400746, -0.009366396, -0.008018757, -0.034123927, 0.029904172, -0.021903709, 0.01853766, -0.011720191, -0.014391078, 0.017757127, 0.0038172943, -0.033050694, -0.009037109, 0.012037283, 0.022184212, -0.014195944, 0.026464948, 0.0009992957, -0.017781518, -0.02724548, 0.013500782, -0.017391251, -0.0041709733, 0.0067259995, -0.009244438, 0.00203213, -0.00011071526, -0.023586731, -0.006616237, 0.031587195, 0.008085834, -0.008171205, -0.02119635, 0.005680207, -0.046905156, -0.03927057, -0.03339218, -0.0066467263, -0.036514312, -0.032465294, 0.024952665, 0.046563674, -0.015842382, -0.0012180584, 0.0035398393, 0.02458679, -0.017708343, 0.0011525057, -0.039782792, -0.021220742, -0.0038203432, 0.018257156, -0.020525578, 0.00018036486, 0.003914861, 0.013866656, 0.021525636, 0.014110574, 0.019415759, 0.047344208, 0.020123117, 0.004521603, -0.00003027519, -0.0036587485, 0.010506706, 0.011146987, 0.011829954, 0.01891573, 0.032782387, 0.015025261, 0.029489513, 0.002265375, 0.020379229, 0.0033416569, 0.027196698, 0.021611009, -0.027147913, -0.017635169, -0.02364771, 0.0012241562, -0.0133666275, -0.0035825246, -0.012208024, 0.019781634, 0.0060796207, -0.018232763, -0.02517219, -0.010659154, 0.009549334, 0.0008948689, -0.02753818, -0.0035002027, 0.025781982, -0.050832212, -0.00052137166, -0.0009375543, 0.01309832, -0.0019437101, 0.013695915, -0.030294437, 0.013976419, 0.010842091, 0.007848016, -0.024611183, -0.015098436, -0.014976477, 0.010970147, -0.013500782, -0.032050636, 0.002523012, 0.0011029602, 0.0045094076, -0.0026800332, -0.026294205, 0.051173694, 0.00005478595, -0.014147161, 0.04844183, 0.017098552, 0.00011309725, 0.02841628, -0.019842613, -0.02797723, 0.010811602, 0.009043206, 0.03207503, -0.0043539107, -0.025099015, 0.007854113, 0.008317555, -0.01391544, -0.050441947, 0.010128636, 0.036172826, 0.035099596, 0.0023858089, 0.03809977, 0.000576634, 0.015013065, 0.010854287, 0.02111098, 0.004420988, 0.016098494, -0.027611356, -0.02002555, 0.018305939, 0.028391888, 0.0056344727, 0.029660255, -0.0073418887, -0.0120311845, -0.0124214515, 0.02736744, -0.0033965383, 0.006933328, 0.011317729, 0.02841628, -0.023391599, -0.06585747, -0.045173347, -0.046563674, 0.029099246, 0.031538412, -0.026269814, 0.0017470524, -0.0016555837, 0.015720423, -0.015842382, -0.02736744, 0.010738427, -0.010470118, -0.02356234, -0.019976767, 0.01648876, -0.0013644083, -0.011903129, -0.0012912333, 0.011427491, -0.008140716, -0.005756431, -0.0040795044, -0.032026246, 0.0064454954, -0.0019299899, 0.017708343, -0.0011166806, 0.013647132, 0.0033965383, 0.00897613, 0.033367787, -0.033075087, 0.0048783314, 0.0033050694, 0.0022150674, 0.007744351, 0.012000695, -0.0070613846, 0.0038660776, 0.014171553, -0.0008460856, 0.0013179117, -0.01967187, -0.026464948, 0.0084517095, 0.028343106, 0.0005484312, -0.012336081, 0.046197798, 0.020952433, -0.015891165, -0.021757359, 0.02096463, -0.044880647, 0.003080971, 0.018366918, 0.0052228635, 0.0084517095, 0.0039605955, -0.011939716, 0.028245538, 0.040831633, -0.03236773, 0.022672044, 0.034221493, 0.0057747248, 0.00025306345, -0.015293568, -0.035099596, -0.014317903, -0.03309948, -0.02648934, 0.018488877, -0.012720249, 0.009665194, -0.03514838, 0.017244902, 0.014013007, -0.038514428, 0.004198414, 0.00768947, 0.020684125, -0.0033203142, 0.01684244, 0.04344154, 0.0013201984, -0.0120311845, -0.034660544, 0.019159647, 0.025050232, 0.0053753112, -0.010098146, 0.032465294, 0.0018796821, 0.010457923, 0.0012066248, 0.022269582, -0.0042868336, 0.020769496, 0.014671582, -0.01339102, -0.03427028, 0.008177303, -0.0418073, -0.00045696244, 0.02826993, 0.0006318964, 0.021354895, 0.022245191, -0.013708111, 0.00026049526, -0.036465526, 0.01055549, -0.010024971, 0.020342642, 0.0028050405, 0.012086066, -0.0061527956, 0.020647537, -0.014147161, -0.005475927, -0.032757994, -0.016659502, -0.029245596, -0.013927636, 0.011775073, -0.0028492503, -0.028879723, 0.023903824, 0.019659676, 0.0033721465, -0.0066650202, 0.02245252, -0.025025839, 0.038050983, 0.023025723, -0.035002027, -0.0054362905, -0.011579939, -0.029050464, 0.016415585, 0.008793192, -0.004113043, -0.03709971, 0.022476912, -0.0046618553, -0.023550145, 0.013025145, 0.042148784, 0.031465236, 0.011616526, 0.025440497, -0.0029300477, -0.0012927578, 0.10420116, -0.002169333, 0.02198908, -0.01891573, -0.0047136876, -0.016318018, 0.019281605, -0.025147798, -0.026830822, 0.010153027, 0.010732329, 0.0069211326, -0.022172015, 0.04417329, -0.010317671, 0.003335559, 0.005491172, -0.033928793, 0.042758573, -0.0094700605, -0.027586963, 0.013903244, 0.00003265719, 0.045514833, -0.001064086, -0.048832096, -0.0024467881, 0.002195249, -0.015732618, 0.004545995, 0.0039179097, -0.012439745, 0.0371241, 0.0017013181, -0.008835877, 0.0041313367, -0.0016875977, 0.015049652, 0.010055461, 0.0009200228, 0.017964454, 0.0146837775, -0.008726115, 0.0032136007, -0.0043935473, 0.017025376, -0.057661876, -0.0018461435, 0.027489398, -0.028391888, -0.01204338, -0.0007081203, -0.0041801203, -0.0024711797, 0.0037563152, 0.018976709, 0.039953534, -0.021001216, 0.017610775, -0.016659502, -0.013415411, 0.023025723, -0.01406179, -0.02546489, 0.0041587777 ] } ] | F3: =LEN(E3)-LEN(SUBSTITUTE(E3,",",""))+1 -> 1536
